Workbook

Sheet Dashboard
B1: DATA INTELLIGENCE DASHBOARD | Customer Transactions
B2: ="Dataset: "&TEXT(MIN('Raw Data'!$B$2:$B$251),"dd-mmm-yyyy")&" to "&TEXT(MAX('Raw Data'!$B$2:$B$251),"dd-mmm-yyyy")&" | Refreshed: "&TEXT(NOW(),"dd-mmm-yyyy hh:mm") -> Dataset: 11-Apr-2024 to 11-Apr-2025 | Refreshed: 15-Oct-2026 11:10 | O2: Criteria helpers
B3: Region | C3: All | D3: Category | E3: All | F3: From | G3: 45393 | H3: To | I3: 45758 | O3: =IF(C3="All","*",C3) -> * | P3: =IF(E3="All","*",E3) -> *
B5: TOTAL REVENUE | D5: ORDERS | F5: UNITS SOLD | H5: AVG ORDER VALUE | J5: ACTIVE CUSTOMERS | L5: ORDERS / CUSTOMER
B6: =SUMIFS('Raw Data'!$N$2:$N$251,'Raw Data'!$K$2:$K$251,$O$3,'Raw Data'!$G$2:$G$251,$P$3,'Raw Data'!$B$2:$B$251,">="&$G$3,'Raw Data'!$B$2:$B$251,"<="&$I$3) -> 229192.47 | D6: =COUNTIFS('Raw Data'!$K$2:$K$251,$O$3,'Raw Data'!$G$2:$G$251,$P$3,'Raw Data'!$B$2:$B$251,">="&$G$3,'Raw Data'!$B$2:$B$251,"<="&$I$3) -> 250 | F6: =SUMIFS('Raw Data'!$H$2:$H$251,'Raw Data'!$K$2:$K$251,$O$3,'Raw Data'!$G$2:$G$251,$P$3,'Raw Data'!$B$2:$B$251,">="&$G$3,'Raw Data'!$B$2:$B$251,"<="&$I$3) -> 753 | H6: =IFERROR(B6/D6,0) -> 916.76988 | J6: =SUMPRODUCT(--(COUNTIFS('Raw Data'!$C$2:$C$251,'Customer Analysis'!$A$23:$A$72,'Raw Data'!$K$2:$K$251,$O$3,'Raw Data'!$G$2:$G$251,$P$3,'Raw Data'!$B$2:$B$251,">="&$G$3,'Raw Data'!$B$2:$B$251,"<="&$I$3)>0)) -> 50 | L6: =IFERROR(D6/J6,0) -> 5
B8: ="Share of all sales: "&TEXT(IFERROR(B6/SUM('Raw Data'!$N$2:$N$251),0),"0.0%") -> Share of all sales: 100.0% | D8: ="Revenue per order "&TEXT(IFERROR(B6/D6,0),"$#,##0") -> Revenue per order $917 | F8: ="Avg "&TEXT(IFERROR(F6/D6,0),"0.0")&" units per order" -> Avg 3.0 units per order | H8: Revenue / Orders | J8: ="of "&COUNTA('Customer Analysis'!$A$23:$A$72)&" total customers" -> of 50 total customers | L8: Purchase frequency
B10: AOV vs OVERALL AVERAGE | D10: LATEST FULL-MONTH GROWTH | F10: REPEAT CUSTOMER RATE | H10: TOP REGION | J10: TOP PRODUCT | L10: TOP CUSTOMER (ALL-TIME)
B11: =IFERROR(H6/(SUM('Raw Data'!$N$2:$N$251)/COUNTA('Raw Data'!$A$2:$A$251))-1,0) -> 0 | D11: ='Sales Analysis'!F71 -> 0.23834149 | F11: ='Customer Analysis'!H4 -> 0.94 | H11: =INDEX(B65:B69,MATCH(MAX(C65:C69),C65:C69,0)) -> East | J11: =INDEX(L65:L74,MATCH(MAX(M65:M74),M65:M74,0)) -> Laptop | L11: ='Customer Analysis'!C9 -> Mark Carter
B13: Selection vs all data | D13: =TEXT('Sales Analysis'!A71,"mmm yyyy")&" vs "&TEXT('Sales Analysis'!A70,"mmm yyyy") -> Mar 2025 vs Feb 2025 | F13: Target: 90%+ (green) | H13: =TEXT(MAX(C65:C69),"$#,##0")&" revenue" -> $59,288 revenue | J13: =TEXT(MAX(M65:M74),"$#,##0")&" revenue" -> $67,499 revenue | L13: =TEXT('Customer Analysis'!D9,"$#,##0")&" revenue" -> $15,660 revenue
B49: Top 5 Customers (all-time) | I49: Payment Mix & Segment
B50: Rank | C50: Customer | E50: Revenue | F50: Orders | G50: % of Total | I50: Payment Method | J50: Revenue | K50: % Share
B51: 1 | C51: ='Customer Analysis'!C9 -> Mark Carter | E51: ='Customer Analysis'!D9 -> 15659.65 | F51: ='Customer Analysis'!E9 -> 12 | G51: ='Customer Analysis'!F9 -> 0.068325325 | I51: ='Sales Analysis'!A22 -> Cash | J51: ='Sales Analysis'!B22 -> 57427.79 | K51: ='Sales Analysis'!F22 -> 0.25056578
B52: 2 | C52: ='Customer Analysis'!C10 -> Edward Mitchell | E52: ='Customer Analysis'!D10 -> 11919.77 | F52: ='Customer Analysis'!E10 -> 6 | G52: ='Customer Analysis'!F10 -> 0.052007686 | I52: ='Sales Analysis'!A23 -> Credit Card | J52: ='Sales Analysis'!B23 -> 61447.96 | K52: ='Sales Analysis'!F23 -> 0.26810636
B53: 3 | C53: ='Customer Analysis'!C11 -> Barbara Young | E53: ='Customer Analysis'!D11 -> 10649.8 | F53: ='Customer Analysis'!E11 -> 5 | G53: ='Customer Analysis'!F11 -> 0.046466623 | I53: ='Sales Analysis'!A24 -> Debit Card | J53: ='Sales Analysis'!B24 -> 52118.31 | K53: ='Sales Analysis'!F24 -> 0.22739975
B54: 4 | C54: ='Customer Analysis'!C12 -> Patricia Moore | E54: ='Customer Analysis'!D12 -> 9799.73 | F54: ='Customer Analysis'!E12 -> 8 | G54: ='Customer Analysis'!F12 -> 0.042757644 | I54: ='Sales Analysis'!A25 -> PayPal | J54: ='Sales Analysis'!B25 -> 58198.41 | K54: ='Sales Analysis'!F25 -> 0.25392811
B55: 5 | C55: ='Customer Analysis'!C13 -> Paul Baker | E55: ='Customer Analysis'!D13 -> 8309.74 | F55: ='Customer Analysis'!E13 -> 8 | G55: ='Customer Analysis'!F13 -> 0.036256601
I56: Segment | J56: Revenue | K56: % Share
I57: ='Sales Analysis'!A30 -> Basic | J57: ='Sales Analysis'!B30 -> 62177.81 | K57: ='Sales Analysis'!F30 -> 0.27129081
I58: ='Sales Analysis'!A31 -> Standard | J58: ='Sales Analysis'!B31 -> 82357.54 | K58: ='Sales Analysis'!F31 -> 0.3593379
I59: ='Sales Analysis'!A32 -> Premium | J59: ='Sales Analysis'!B32 -> 84657.12 | K59: ='Sales Analysis'!F32 -> 0.3693713
B63: Chart data (recalculates with the filters above)
B64: Region | C64: Revenue | E64: Month Start | F64: Month | G64: Revenue | I64: Category | J64: Revenue | L64: Product | M64: Revenue
B65: Central | C65: =SUMIFS('Raw Data'!$N$2:$N$251,'Raw Data'!$K$2:$K$251,B65,'Raw Data'!$G$2:$G$251,$P$3,'Raw Data'!$B$2:$B$251,">="&$G$3,'Raw Data'!$B$2:$B$251,"<="&$I$3) -> 41288.34 | E65: ='Sales Analysis'!$A$60 -> 45383 | F65: =TEXT(E65,"mmm-yy") -> Apr-24 | G65: =SUMIFS('Raw Data'!$N$2:$N$251,'Raw Data'!$K$2:$K$251,$O$3,'Raw Data'!$G$2:$G$251,$P$3,'Raw Data'!$B$2:$B$251,">="&MAX(E65,$G$3),'Raw Data'!$B$2:$B$251,"<="&MIN(EOMONTH(E65,0),$I$3)) -> 20919.33 | I65: Appliances | J65: =SUMIFS('Raw Data'!$N$2:$N$251,'Raw Data'!$G$2:$G$251,I65,'Raw Data'!$K$2:$K$251,$O$3,'Raw Data'!$B$2:$B$251,">="&$G$3,'Raw Data'!$B$2:$B$251,"<="&$I$3) -> 8338.74 | L65: ='Sales Analysis'!$A$37 -> Laptop | M65: =SUMIFS('Raw Data'!$N$2:$N$251,'Raw Data'!$F$2:$F$251,L65,'Raw Data'!$K$2:$K$251,$O$3,'Raw Data'!$G$2:$G$251,$P$3,'Raw Data'!$B$2:$B$251,">="&$G$3,'Raw Data'!$B$2:$B$251,"<="&$I$3) -> 67499.25
B66: East | C66: =SUMIFS('Raw Data'!$N$2:$N$251,'Raw Data'!$K$2:$K$251,B66,'Raw Data'!$G$2:$G$251,$P$3,'Raw Data'!$B$2:$B$251,">="&$G$3,'Raw Data'!$B$2:$B$251,"<="&$I$3) -> 59288.39 | E66: ='Sales Analysis'!$A$61 -> 45413 | F66: =TEXT(E66,"mmm-yy") -> May-24 | G66: =SUMIFS('Raw Data'!$N$2:$N$251,'Raw Data'!$K$2:$K$251,$O$3,'Raw Data'!$G$2:$G$251,$P$3,'Raw Data'!$B$2:$B$251,">="&MAX(E66,$G$3),'Raw Data'!$B$2:$B$251,"<="&MIN(EOMONTH(E66,0),$I$3)) -> 17039.35 | I66: Electronics | J66: =SUMIFS('Raw Data'!$N$2:$N$251,'Raw Data'!$G$2:$G$251,I66,'Raw Data'!$K$2:$K$251,$O$3,'Raw Data'!$B$2:$B$251,">="&$G$3,'Raw Data'!$B$2:$B$251,"<="&$I$3) -> 171756.05 | L66: ='Sales Analysis'!$A$38 -> Smartphone | M66: =SUMIFS('Raw Data'!$N$2:$N$251,'Raw Data'!$F$2:$F$251,L66,'Raw Data'!$K$2:$K$251,$O$3,'Raw Data'!$G$2:$G$251,$P$3,'Raw Data'!$B$2:$B$251,">="&$G$3,'Raw Data'!$B$2:$B$251,"<="&$I$3) -> 67199.04
B67: North | C67: =SUMIFS('Raw Data'!$N$2:$N$251,'Raw Data'!$K$2:$K$251,B67,'Raw Data'!$G$2:$G$251,$P$3,'Raw Data'!$B$2:$B$251,">="&$G$3,'Raw Data'!$B$2:$B$251,"<="&$I$3) -> 50808.31 | E67: ='Sales Analysis'!$A$62 -> 45444 | F67: =TEXT(E67,"mmm-yy") -> Jun-24 | G67: =SUMIFS('Raw Data'!$N$2:$N$251,'Raw Data'!$K$2:$K$251,$O$3,'Raw Data'!$G$2:$G$251,$P$3,'Raw Data'!$B$2:$B$251,">="&MAX(E67,$G$3),'Raw Data'!$B$2:$B$251,"<="&MIN(EOMONTH(E67,0),$I$3)) -> 19299.45 | I67: Furniture | J67: =SUMIFS('Raw Data'!$N$2:$N$251,'Raw Data'!$G$2:$G$251,I67,'Raw Data'!$K$2:$K$251,$O$3,'Raw Data'!$B$2:$B$251,">="&$G$3,'Raw Data'!$B$2:$B$251,"<="&$I$3) -> 49097.68 | L67: ='Sales Analysis'!$A$39 -> Headphones | M67: =SUMIFS('Raw Data'!$N$2:$N$251,'Raw Data'!$F$2:$F$251,L67,'Raw Data'!$K$2:$K$251,$O$3,'Raw Data'!$G$2:$G$251,$P$3,'Raw Data'!$B$2:$B$251,">="&$G$3,'Raw Data'!$B$2:$B$251,"<="&$I$3) -> 7049.53
B68: South | C68: =SUMIFS('Raw Data'!$N$2:$N$251,'Raw Data'!$K$2:$K$251,B68,'Raw Data'!$G$2:$G$251,$P$3,'Raw Data'!$B$2:$B$251,">="&$G$3,'Raw Data'!$B$2:$B$251,"<="&$I$3) -> 36398.75 | E68: ='Sales Analysis'!$A$63 -> 45474 | F68: =TEXT(E68,"mmm-yy") -> Jul-24 | G68: =SUMIFS('Raw Data'!$N$2:$N$251,'Raw Data'!$K$2:$K$251,$O$3,'Raw Data'!$G$2:$G$251,$P$3,'Raw Data'!$B$2:$B$251,">="&MAX(E68,$G$3),'Raw Data'!$B$2:$B$251,"<="&MIN(EOMONTH(E68,0),$I$3)) -> 18479.4 | L68: ='Sales Analysis'!$A$40 -> Coffee Maker | M68: =SUMIFS('Raw Data'!$N$2:$N$251,'Raw Data'!$F$2:$F$251,L68,'Raw Data'!$K$2:$K$251,$O$3,'Raw Data'!$G$2:$G$251,$P$3,'Raw Data'!$B$2:$B$251,">="&$G$3,'Raw Data'!$B$2:$B$251,"<="&$I$3) -> 3119.61
B69: West | C69: =SUMIFS('Raw Data'!$N$2:$N$251,'Raw Data'!$K$2:$K$251,B69,'Raw Data'!$G$2:$G$251,$P$3,'Raw Data'!$B$2:$B$251,">="&$G$3,'Raw Data'!$B$2:$B$251,"<="&$I$3) -> 41408.68 | E69: ='Sales Analysis'!$A$64 -> 45505 | F69: =TEXT(E69,"mmm-yy") -> Aug-24 | G69: =SUMIFS('Raw Data'!$N$2:$N$251,'Raw Data'!$K$2:$K$251,$O$3,'Raw Data'!$G$2:$G$251,$P$3,'Raw Data'!$B$2:$B$251,">="&MAX(E69,$G$3),'Raw Data'!$B$2:$B$251,"<="&MIN(EOMONTH(E69,0),$I$3)) -> 15759.43 | L69: ='Sales Analysis'!$A$41 -> Blender | M69: =SUMIFS('Raw Data'!$N$2:$N$251,'Raw Data'!$F$2:$F$251,L69,'Raw Data'!$K$2:$K$251,$O$3,'Raw Data'!$G$2:$G$251,$P$3,'Raw Data'!$B$2:$B$251,">="&$G$3,'Raw Data'!$B$2:$B$251,"<="&$I$3) -> 5219.13
E70: ='Sales Analysis'!$A$65 -> 45536 | F70: =TEXT(E70,"mmm-yy") -> Sep-24 | G70: =SUMIFS('Raw Data'!$N$2:$N$251,'Raw Data'!$K$2:$K$251,$O$3,'Raw Data'!$G$2:$G$251,$P$3,'Raw Data'!$B$2:$B$251,">="&MAX(E70,$G$3),'Raw Data'!$B$2:$B$251,"<="&MIN(EOMONTH(E70,0),$I$3)) -> 12989.51 | L70: ='Sales Analysis'!$A$42 -> Office Chair | M70: =SUMIFS('Raw Data'!$N$2:$N$251,'Raw Data'!$F$2:$F$251,L70,'Raw Data'!$K$2:$K$251,$O$3,'Raw Data'!$G$2:$G$251,$P$3,'Raw Data'!$B$2:$B$251,">="&$G$3,'Raw Data'!$B$2:$B$251,"<="&$I$3) -> 10399.48
E71: ='Sales Analysis'!$A$66 -> 45566 | F71: =TEXT(E71,"mmm-yy") -> Oct-24 | G71: =SUMIFS('Raw Data'!$N$2:$N$251,'Raw Data'!$K$2:$K$251,$O$3,'Raw Data'!$G$2:$G$251,$P$3,'Raw Data'!$B$2:$B$251,">="&MAX(E71,$G$3),'Raw Data'!$B$2:$B$251,"<="&MIN(EOMONTH(E71,0),$I$3)) -> 20609.52 | L71: ='Sales Analysis'!$A$43 -> Desk | M71: =SUMIFS('Raw Data'!$N$2:$N$251,'Raw Data'!$F$2:$F$251,L71,'Raw Data'!$K$2:$K$251,$O$3,'Raw Data'!$G$2:$G$251,$P$3,'Raw Data'!$B$2:$B$251,">="&$G$3,'Raw Data'!$B$2:$B$251,"<="&$I$3) -> 23399.22
E72: ='Sales Analysis'!$A$67 -> 45597 | F72: =TEXT(E72,"mmm-yy") -> Nov-24 | G72: =SUMIFS('Raw Data'!$N$2:$N$251,'Raw Data'!$K$2:$K$251,$O$3,'Raw Data'!$G$2:$G$251,$P$3,'Raw Data'!$B$2:$B$251,">="&MAX(E72,$G$3),'Raw Data'!$B$2:$B$251,"<="&MIN(EOMONTH(E72,0),$I$3)) -> 12309.44 | L72: ='Sales Analysis'!$A$44 -> Bookshelf | M72: =SUMIFS('Raw Data'!$N$2:$N$251,'Raw Data'!$F$2:$F$251,L72,'Raw Data'!$K$2:$K$251,$O$3,'Raw Data'!$G$2:$G$251,$P$3,'Raw Data'!$B$2:$B$251,">="&$G$3,'Raw Data'!$B$2:$B$251,"<="&$I$3) -> 15298.98
E73: ='Sales Analysis'!$A$68 -> 45627 | F73: =TEXT(E73,"mmm-yy") -> Dec-24 | G73: =SUMIFS('Raw Data'!$N$2:$N$251,'Raw Data'!$K$2:$K$251,$O$3,'Raw Data'!$G$2:$G$251,$P$3,'Raw Data'!$B$2:$B$251,">="&MAX(E73,$G$3),'Raw Data'!$B$2:$B$251,"<="&MIN(EOMONTH(E73,0),$I$3)) -> 23039.3 | L73: ='Sales Analysis'!$A$45 -> Monitor | M73: =SUMIFS('Raw Data'!$N$2:$N$251,'Raw Data'!$F$2:$F$251,L73,'Raw Data'!$K$2:$K$251,$O$3,'Raw Data'!$G$2:$G$251,$P$3,'Raw Data'!$B$2:$B$251,">="&$G$3,'Raw Data'!$B$2:$B$251,"<="&$I$3) -> 21999.12
E74: ='Sales Analysis'!$A$69 -> 45658 | F74: =TEXT(E74,"mmm-yy") -> Jan-25 | G74: =SUMIFS('Raw Data'!$N$2:$N$251,'Raw Data'!$K$2:$K$251,$O$3,'Raw Data'!$G$2:$G$251,$P$3,'Raw Data'!$B$2:$B$251,">="&MAX(E74,$G$3),'Raw Data'!$B$2:$B$251,"<="&MIN(EOMONTH(E74,0),$I$3)) -> 25799.15 | L74: ='Sales Analysis'!$A$46 -> Keyboard | M74: =SUMIFS('Raw Data'!$N$2:$N$251,'Raw Data'!$F$2:$F$251,L74,'Raw Data'!$K$2:$K$251,$O$3,'Raw Data'!$G$2:$G$251,$P$3,'Raw Data'!$B$2:$B$251,">="&$G$3,'Raw Data'!$B$2:$B$251,"<="&$I$3) -> 8009.11
E75: ='Sales Analysis'!$A$70 -> 45689 | F75: =TEXT(E75,"mmm-yy") -> Feb-25 | G75: =SUMIFS('Raw Data'!$N$2:$N$251,'Raw Data'!$K$2:$K$251,$O$3,'Raw Data'!$G$2:$G$251,$P$3,'Raw Data'!$B$2:$B$251,">="&MAX(E75,$G$3),'Raw Data'!$B$2:$B$251,"<="&MIN(EOMONTH(E75,0),$I$3)) -> 16069.38
E76: ='Sales Analysis'!$A$71 -> 45717 | F76: =TEXT(E76,"mmm-yy") -> Mar-25 | G76: =SUMIFS('Raw Data'!$N$2:$N$251,'Raw Data'!$K$2:$K$251,$O$3,'Raw Data'!$G$2:$G$251,$P$3,'Raw Data'!$B$2:$B$251,">="&MAX(E76,$G$3),'Raw Data'!$B$2:$B$251,"<="&MIN(EOMONTH(E76,0),$I$3)) -> 19899.38
E77: ='Sales Analysis'!$A$72 -> 45748 | F77: =TEXT(E77,"mmm-yy") -> Apr-25 | G77: =SUMIFS('Raw Data'!$N$2:$N$251,'Raw Data'!$K$2:$K$251,$O$3,'Raw Data'!$G$2:$G$251,$P$3,'Raw Data'!$B$2:$B$251,">="&MAX(E77,$G$3),'Raw Data'!$B$2:$B$251,"<="&MIN(EOMONTH(E77,0),$I$3)) -> 6979.83

Sheet Executive Charts
B1: EXECUTIVE CHARTS | Customer Transactions Analytics
B2: ="Dataset: "&TEXT(MIN('Raw Data'!$B$2:$B$251),"dd-mmm-yyyy")&" to "&TEXT(MAX('Raw Data'!$B$2:$B$251),"dd-mmm-yyyy") -> Dataset: 11-Apr-2024 to 11-Apr-2025 | T2: << Dashboard
B4: TOTAL REVENUE | F4: AVG ORDER VALUE | J4: UNITS SOLD | N4: ACTIVE CUSTOMERS | R4: REPEAT CUSTOMER RATE
B5: ='Sales Analysis'!B11 -> 229192.47 | F5: ='Sales Analysis'!E11 -> 916.76988 | J5: ='Sales Analysis'!D11 -> 753 | N5: =COUNTA('Customer Analysis'!$A$23:$A$72) -> 50 | R5: ='Customer Analysis'!H4 -> 0.94
B7: ="Across "&TEXT('Sales Analysis'!C11,"#,##0")&" orders" -> Across 250 orders | F7: ="Revenue / orders" -> Revenue / orders | J7: ="Avg "&TEXT('Sales Analysis'!D11/'Sales Analysis'!C11,"0.0")&" units per order" -> Avg 3.0 units per order | N7: ="Top 10 = "&TEXT('Customer Analysis'!F19,"0.0%")&" of revenue" -> Top 10 = 41.0% of revenue | R7: ="Customers with 2+ orders" -> Customers with 2+ orders
B9: 1 REVENUE TREND & MOMENTUM
B46: 2 PRODUCT & CATEGORY MIX
B83: 3 REGIONAL & PAYMENT PERFORMANCE
B120: 4 CUSTOMER INSIGHTS

Sheet Visualizations
A1: Visualizations

Sheet Insights Report
A1: Insights Report - Data Storytelling
B4: Executive Summary
B5: ="Between "&TEXT(MIN('Raw Data'!$B$2:$B$251),"mmm yyyy")&" and "&TEXT(MAX('Raw Data'!$B$2:$B$251),"mmm yyyy")&", "&TEXT('Sales Analysis'!C11,"#,##0")&" orders from "&COUNTA('Customer Analysis'!$A$23:$A$72)&" customers generated "&TEXT('Sales Analysis'!B11,"$#,##0")&" in revenue (average order "&TEXT('Sales Analysis'!E11,"$#,##0")&"). Sales are concentrated in a few products, one category and a small group of high-value customers - which is both the opportunity and the risk." -> Between Apr 2024 and Apr 2025, 250 orders from 50 customers generated $2,29,192 in revenue (average order $917). Sales are concentrated in a few products, one category and a small group of high-value customers - which is both the opportunity and the risk.
B7: Key metric | C7: Value
B8: Total Revenue | C8: ='Sales Analysis'!B11 -> 229192.47
B9: Orders | C9: ='Sales Analysis'!C11 -> 250
B10: Customers | C10: =COUNTA('Customer Analysis'!$A$23:$A$72) -> 50
B11: Avg Order Value | C11: ='Sales Analysis'!E11 -> 916.76988
A13: # | B13: Theme | C13: What the data says | D13: So what - recommendation
A14: 1 | B14: Category mix | C14: =INDEX('Sales Analysis'!$A$15:$A$17,MATCH(MAX('Sales Analysis'!$B$15:$B$17),'Sales Analysis'!$B$15:$B$17,0))&" generates "&TEXT(MAX('Sales Analysis'!$F$15:$F$17),"0.0%")&" of revenue ("&TEXT(MAX('Sales Analysis'!$B$15:$B$17),"$#,##0")&"), while "&INDEX('Sales Analysis'!$A$15:$A$17,MATCH(MIN('Sales Analysis'!$B$15:$B$17),'Sales Analysis'!$B$15:$B$17,0))&" adds only "&TEXT(MIN('Sales Analysis'!$F$15:$F$17),"0.0%")&"." -> Electronics generates 74.9% of revenue ($1,71,756), while Appliances adds only 3.6%. | D14: Protect the electronics franchise (stock, pricing, supplier terms). Lift low-value appliance baskets with bundles and add-on offers.
A15: 2 | B15: Product concentration | C15: ="Top two products by revenue - "&INDEX('Sales Analysis'!$A$37:$A$46,MATCH(LARGE('Sales Analysis'!$B$37:$B$46,1),'Sales Analysis'!$B$37:$B$46,0))&" and "&INDEX('Sales Analysis'!$A$37:$A$46,MATCH(LARGE('Sales Analysis'!$B$37:$B$46,2),'Sales Analysis'!$B$37:$B$46,0))&" - deliver "&TEXT((LARGE('Sales Analysis'!$B$37:$B$46,1)+LARGE('Sales Analysis'!$B$37:$B$46,2))/'Sales Analysis'!B47,"0.0%")&" of revenue from only "&TEXT((INDEX('Sales Analysis'!$C$37:$C$46,MATCH(LARGE('Sales Analysis'!$B$37:$B$46,1),'Sales Analysis'!$B$37:$B$46,0))+INDEX('Sales Analysis'!$C$37:$C$46,MATCH(LARGE('Sales Analysis'!$B$37:$B$46,2),'Sales Analysis'!$B$37:$B$46,0)))/'Sales Analysis'!C47,"0.0%")&" of orders." -> Top two products by revenue - Laptop and Smartphone - deliver 58.8% of revenue from only 22.0% of orders. | D15: Cross-sell accessories (keyboards, monitors, headphones) at checkout for premium devices; monitor stock-outs on the top two SKUs.
A16: 3 | B16: Volume vs value | C16: ="Most frequently ordered product is "&'Names & Lists'!B17&" ("&'Names & Lists'!C17&") but it ranks #"&INDEX('Sales Analysis'!$G$37:$G$46,MATCH('Names & Lists'!B17,'Sales Analysis'!$A$37:$A$46,0))&" by revenue; the highest-revenue product is "&'Names & Lists'!B19&"." -> Most frequently ordered product is Bookshelf (35 orders) but it ranks #5 by revenue; the highest-revenue product is Laptop. | D16: Use high-frequency, lower-ticket items as traffic builders and pair them with high-ticket items to grow basket value.
A17: 4 | B17: Regional performance | C17: ="Best region: "&INDEX('Sales Analysis'!$A$6:$A$10,MATCH(MAX('Sales Analysis'!$B$6:$B$10),'Sales Analysis'!$B$6:$B$10,0))&" ("&TEXT(MAX('Sales Analysis'!$B$6:$B$10),"$#,##0")&", "&TEXT(INDEX('Sales Analysis'!$F$6:$F$10,MATCH(MAX('Sales Analysis'!$B$6:$B$10),'Sales Analysis'!$B$6:$B$10,0)),"0.0%")&" of sales). Weakest: "&INDEX('Sales Analysis'!$A$6:$A$10,MATCH(MIN('Sales Analysis'!$B$6:$B$10),'Sales Analysis'!$B$6:$B$10,0))&" ("&TEXT(MIN('Sales Analysis'!$B$6:$B$10),"$#,##0")&") - a gap of "&TEXT(MAX('Sales Analysis'!$B$6:$B$10)/MIN('Sales Analysis'!$B$6:$B$10)-1,"0%")&"." -> Best region: East ($59,288, 25.9% of sales). Weakest: South ($36,399) - a gap of 63%. | D17: Replicate the best region's playbook; run a diagnostic and targeted campaign in the weakest region before adding spend.
A18: 5 | B18: Customer concentration | C18: ="Top customer "&'Customer Analysis'!C9&" contributes "&TEXT('Customer Analysis'!F9,"0.0%")&" of revenue; the top 10 customers contribute "&TEXT('Customer Analysis'!G18,"0.0%")&". "&'Customer Analysis'!E3&" High-Value customers (top "&TEXT(1-'Customer Analysis'!B3,"0%")&") generate "&TEXT('Customer Analysis'!E5,"0.0%")&" of sales." -> Top customer Mark Carter contributes 6.8% of revenue; the top 10 customers contribute 41.0%. 10 High-Value customers (top 20%) generate 41.0% of sales. | D18: Assign account managers and loyalty perks to High-Value customers; track their order frequency as an early-warning KPI.
A19: 6 | B19: Repeat behaviour | C19: =TEXT('Customer Analysis'!H4,"0%")&" of customers bought more than once ("&'Customer Analysis'!H3&" of "&COUNTA('Customer Analysis'!$A$23:$A$72)&"). Most frequent buyer: "&'Names & Lists'!B25&" with "&'Names & Lists'!C25&"." -> 94% of customers bought more than once (47 of 50). Most frequent buyer: Mark Carter with 12 transactions. | D19: Retention is strong - shift focus from re-activation to increasing spend per visit (upsell, bundles, subscriptions).
A20: 7 | B20: Seasonality | C20: ="Among full months, revenue peaked in "&TEXT(INDEX('Sales Analysis'!$A$61:$A$71,MATCH(MAX('Sales Analysis'!$C$61:$C$71),'Sales Analysis'!$C$61:$C$71,0)),"mmm yyyy")&" ("&TEXT(MAX('Sales Analysis'!$C$61:$C$71),"$#,##0")&") and bottomed in "&TEXT(INDEX('Sales Analysis'!$A$61:$A$71,MATCH(MIN('Sales Analysis'!$C$61:$C$71),'Sales Analysis'!$C$61:$C$71,0)),"mmm yyyy")&" ("&TEXT(MIN('Sales Analysis'!$C$61:$C$71),"$#,##0")&")." -> Among full months, revenue peaked in Jan 2025 ($25,799) and bottomed in Nov 2024 ($12,309). | D20: Plan inventory and promotions around peak months; use targeted offers to lift the slow months. Note first/last month are partial.
A21: 8 | B21: Payment mix | C21: ="Most-used method by revenue: "&INDEX('Sales Analysis'!$A$22:$A$25,MATCH(MAX('Sales Analysis'!$B$22:$B$25),'Sales Analysis'!$B$22:$B$25,0))&" ("&TEXT(MAX('Sales Analysis'!$F$22:$F$25),"0.0%")&"); the spread between top and bottom method is only "&TEXT((MAX('Sales Analysis'!$F$22:$F$25)-MIN('Sales Analysis'!$F$22:$F$25))*100,"0.0")&" percentage points." -> Most-used method by revenue: Credit Card (26.8%); the spread between top and bottom method is only 4.1 percentage points. | D21: No payment dependency risk - keep all four methods; test small incentives on lower-cost rails.
A22: 9 | B22: Regression drivers | C22: ="Order value = "&TEXT(Regression!B18,"$#,##0")&" + "&TEXT(Regression!B19,"$#,##0")&" per extra unit + "&TEXT(Regression!B20,"$#,##0.00")&" per $1 of unit price (R-squared "&TEXT(Regression!B7,"0.00")&"). Monthly trend is "&IF(Regression!E41<0.05,"significant","NOT statistically significant")&" (p = "&TEXT(Regression!E41,"0.00")&")." -> Order value = -$932 + $314 per extra unit + $3.04 per $1 of unit price (R-squared 0.86). Monthly trend is NOT statistically significant (p = 0.41). | D22: Both quantity and price move order value, so volume incentives and premium mix both pay off. Do not extrapolate a trend - demand is seasonal/volatile.
A23: 10 | B23: Data quality | C23: ="Customer_Since holds conflicting dates for "&'Customer Analysis'!H5&" of "&COUNTA('Customer Analysis'!$A$23:$A$72)&" customers; Region and Segment also change between transactions of the same Customer_ID." -> Customer_Since holds conflicting dates for 47 of 50 customers; Region and Segment also change between transactions of the same Customer_ID. | D23: Fix the customer master (one record per customer) before using segment/tenure for decisions; treat current segment cuts as transaction-level.

Sheet Sales Analysis
A1: Sales Analysis
A4: 1. Revenue by Region
A5: Region | B5: Revenue | C5: Orders | D5: Units Sold | E5: Avg Order Value | F5: % of Revenue | G5: Rank
A6: Central | B6: =SUMIFS('Raw Data'!$N$2:$N$251,'Raw Data'!$K$2:$K$251,$A6) -> 41288.34 | C6: =COUNTIFS('Raw Data'!$K$2:$K$251,$A6) -> 54 | D6: =SUMIFS('Raw Data'!$H$2:$H$251,'Raw Data'!$K$2:$K$251,$A6) -> 166 | E6: =IFERROR(B6/C6,0) -> 764.59889 | F6: =B6/$B$11 -> 0.18014702 | G6: =RANK(B6,$B$6:$B$10,0) -> 4
A7: East | B7: =SUMIFS('Raw Data'!$N$2:$N$251,'Raw Data'!$K$2:$K$251,$A7) -> 59288.39 | C7: =COUNTIFS('Raw Data'!$K$2:$K$251,$A7) -> 48 | D7: =SUMIFS('Raw Data'!$H$2:$H$251,'Raw Data'!$K$2:$K$251,$A7) -> 161 | E7: =IFERROR(B7/C7,0) -> 1235.1748 | F7: =B7/$B$11 -> 0.25868385 | G7: =RANK(B7,$B$6:$B$10,0) -> 1
A8: North | B8: =SUMIFS('Raw Data'!$N$2:$N$251,'Raw Data'!$K$2:$K$251,$A8) -> 50808.31 | C8: =COUNTIFS('Raw Data'!$K$2:$K$251,$A8) -> 59 | D8: =SUMIFS('Raw Data'!$H$2:$H$251,'Raw Data'!$K$2:$K$251,$A8) -> 169 | E8: =IFERROR(B8/C8,0) -> 861.1578 | F8: =B8/$B$11 -> 0.22168403 | G8: =RANK(B8,$B$6:$B$10,0) -> 2
A9: South | B9: =SUMIFS('Raw Data'!$N$2:$N$251,'Raw Data'!$K$2:$K$251,$A9) -> 36398.75 | C9: =COUNTIFS('Raw Data'!$K$2:$K$251,$A9) -> 42 | D9: =SUMIFS('Raw Data'!$H$2:$H$251,'Raw Data'!$K$2:$K$251,$A9) -> 125 | E9: =IFERROR(B9/C9,0) -> 866.6369 | F9: =B9/$B$11 -> 0.15881303 | G9: =RANK(B9,$B$6:$B$10,0) -> 5
A10: West | B10: =SUMIFS('Raw Data'!$N$2:$N$251,'Raw Data'!$K$2:$K$251,$A10) -> 41408.68 | C10: =COUNTIFS('Raw Data'!$K$2:$K$251,$A10) -> 47 | D10: =SUMIFS('Raw Data'!$H$2:$H$251,'Raw Data'!$K$2:$K$251,$A10) -> 132 | E10: =IFERROR(B10/C10,0) -> 881.03574 | F10: =B10/$B$11 -> 0.18067208 | G10: =RANK(B10,$B$6:$B$10,0) -> 3
A11: Total | B11: =SUM(B6:B10) -> 229192.47 | C11: =SUM(C6:C10) -> 250 | D11: =SUM(D6:D10) -> 753 | E11: =B11/C11 -> 916.76988 | F11: =SUM(F6:F10) -> 1
A13: 2. Revenue by Category
A14: Category | B14: Revenue | C14: Orders | D14: Units Sold | E14: Avg Order Value | F14: % of Revenue | G14: Rank
A15: Appliances | B15: =SUMIFS('Raw Data'!$N$2:$N$251,'Raw Data'!$G$2:$G$251,$A15) -> 8338.74 | C15: =COUNTIFS('Raw Data'!$G$2:$G$251,$A15) -> 43 | D15: =SUMIFS('Raw Data'!$H$2:$H$251,'Raw Data'!$G$2:$G$251,$A15) -> 126 | E15: =IFERROR(B15/C15,0) -> 193.92419 | F15: =B15/$B$18 -> 0.036383132 | G15: =RANK(B15,$B$15:$B$17,0) -> 3
A16: Electronics | B16: =SUMIFS('Raw Data'!$N$2:$N$251,'Raw Data'!$G$2:$G$251,$A16) -> 171756.05 | C16: =COUNTIFS('Raw Data'!$G$2:$G$251,$A16) -> 131 | D16: =SUMIFS('Raw Data'!$H$2:$H$251,'Raw Data'!$G$2:$G$251,$A16) -> 395 | E16: =IFERROR(B16/C16,0) -> 1311.1149 | F16: =B16/$B$18 -> 0.74939657 | G16: =RANK(B16,$B$15:$B$17,0) -> 1
A17: Furniture | B17: =SUMIFS('Raw Data'!$N$2:$N$251,'Raw Data'!$G$2:$G$251,$A17) -> 49097.68 | C17: =COUNTIFS('Raw Data'!$G$2:$G$251,$A17) -> 76 | D17: =SUMIFS('Raw Data'!$H$2:$H$251,'Raw Data'!$G$2:$G$251,$A17) -> 232 | E17: =IFERROR(B17/C17,0) -> 646.02211 | F17: =B17/$B$18 -> 0.2142203 | G17: =RANK(B17,$B$15:$B$17,0) -> 2
A18: Total | B18: =SUM(B15:B17) -> 229192.47 | C18: =SUM(C15:C17) -> 250 | D18: =SUM(D15:D17) -> 753 | E18: =B18/C18 -> 916.76988 | F18: =SUM(F15:F17) -> 1
A20: 3. Revenue by Payment Method
A21: Payment Method | B21: Revenue | C21: Orders | D21: Units Sold | E21: Avg Order Value | F21: % of Revenue | G21: Rank
A22: Cash | B22: =SUMIFS('Raw Data'!$N$2:$N$251,'Raw Data'!$J$2:$J$251,$A22) -> 57427.79 | C22: =COUNTIFS('Raw Data'!$J$2:$J$251,$A22) -> 76 | D22: =SUMIFS('Raw Data'!$H$2:$H$251,'Raw Data'!$J$2:$J$251,$A22) -> 221 | E22: =IFERROR(B22/C22,0) -> 755.62882 | F22: =B22/$B$26 -> 0.25056578 | G22: =RANK(B22,$B$22:$B$25,0) -> 3
A23: Credit Card | B23: =SUMIFS('Raw Data'!$N$2:$N$251,'Raw Data'!$J$2:$J$251,$A23) -> 61447.96 | C23: =COUNTIFS('Raw Data'!$J$2:$J$251,$A23) -> 68 | D23: =SUMIFS('Raw Data'!$H$2:$H$251,'Raw Data'!$J$2:$J$251,$A23) -> 204 | E23: =IFERROR(B23/C23,0) -> 903.64647 | F23: =B23/$B$26 -> 0.26810636 | G23: =RANK(B23,$B$22:$B$25,0) -> 1
A24: Debit Card | B24: =SUMIFS('Raw Data'!$N$2:$N$251,'Raw Data'!$J$2:$J$251,$A24) -> 52118.31 | C24: =COUNTIFS('Raw Data'!$J$2:$J$251,$A24) -> 54 | D24: =SUMIFS('Raw Data'!$H$2:$H$251,'Raw Data'!$J$2:$J$251,$A24) -> 169 | E24: =IFERROR(B24/C24,0) -> 965.15389 | F24: =B24/$B$26 -> 0.22739975 | G24: =RANK(B24,$B$22:$B$25,0) -> 4
A25: PayPal | B25: =SUMIFS('Raw Data'!$N$2:$N$251,'Raw Data'!$J$2:$J$251,$A25) -> 58198.41 | C25: =COUNTIFS('Raw Data'!$J$2:$J$251,$A25) -> 52 | D25: =SUMIFS('Raw Data'!$H$2:$H$251,'Raw Data'!$J$2:$J$251,$A25) -> 159 | E25: =IFERROR(B25/C25,0) -> 1119.2002 | F25: =B25/$B$26 -> 0.25392811 | G25: =RANK(B25,$B$22:$B$25,0) -> 2
A26: Total | B26: =SUM(B22:B25) -> 229192.47 | C26: =SUM(C22:C25) -> 250 | D26: =SUM(D22:D25) -> 753 | E26: =B26/C26 -> 916.76988 | F26: =SUM(F22:F25) -> 1
A28: 4. Revenue by Customer Segment (as recorded per transaction)
A29: Segment | B29: Revenue | C29: Orders | D29: Units Sold | E29: Avg Order Value | F29: % of Revenue | G29: Rank
A30: Basic | B30: =SUMIFS('Raw Data'!$N$2:$N$251,'Raw Data'!$L$2:$L$251,$A30) -> 62177.81 | C30: =COUNTIFS('Raw Data'!$L$2:$L$251,$A30) -> 74 | D30: =SUMIFS('Raw Data'!$H$2:$H$251,'Raw Data'!$L$2:$L$251,$A30) -> 219 | E30: =IFERROR(B30/C30,0) -> 840.24068 | F30: =B30/$B$33 -> 0.27129081 | G30: =RANK(B30,$B$30:$B$32,0) -> 3
A31: Standard | B31: =SUMIFS('Raw Data'!$N$2:$N$251,'Raw Data'!$L$2:$L$251,$A31) -> 82357.54 | C31: =COUNTIFS('Raw Data'!$L$2:$L$251,$A31) -> 81 | D31: =SUMIFS('Raw Data'!$H$2:$H$251,'Raw Data'!$L$2:$L$251,$A31) -> 246 | E31: =IFERROR(B31/C31,0) -> 1016.7598 | F31: =B31/$B$33 -> 0.3593379 | G31: =RANK(B31,$B$30:$B$32,0) -> 2
A32: Premium | B32: =SUMIFS('Raw Data'!$N$2:$N$251,'Raw Data'!$L$2:$L$251,$A32) -> 84657.12 | C32: =COUNTIFS('Raw Data'!$L$2:$L$251,$A32) -> 95 | D32: =SUMIFS('Raw Data'!$H$2:$H$251,'Raw Data'!$L$2:$L$251,$A32) -> 288 | E32: =IFERROR(B32/C32,0) -> 891.12758 | F32: =B32/$B$33 -> 0.3693713 | G32: =RANK(B32,$B$30:$B$32,0) -> 1
A33: Total | B33: =SUM(B30:B32) -> 229192.47 | C33: =SUM(C30:C32) -> 250 | D33: =SUM(D30:D32) -> 753 | E33: =B33/C33 -> 916.76988 | F33: =SUM(F30:F32) -> 1
A35: 5. Revenue by Product
A36: Product | B36: Revenue | C36: Orders | D36: Units Sold | E36: Avg Order Value | F36: % of Revenue | G36: Rank | H36: Product ID | I36: Category | J36: Abbreviation | K36: Orders Rank
A37: Laptop | B37: =SUMIFS('Raw Data'!$N$2:$N$251,'Raw Data'!$F$2:$F$251,$A37) -> 67499.25 | C37: =COUNTIFS('Raw Data'!$F$2:$F$251,$A37) -> 24 | D37: =SUMIFS('Raw Data'!$H$2:$H$251,'Raw Data'!$F$2:$F$251,$A37) -> 75 | E37: =IFERROR(B37/C37,0) -> 2812.4688 | F37: =B37/$B$47 -> 0.29450902 | G37: =RANK(B37,$B$37:$B$46,0) -> 1 | H37: =INDEX('Raw Data'!$E$2:$E$251,MATCH($A37,'Raw Data'!$F$2:$F$251,0)) -> P001 | I37: =INDEX('Raw Data'!$G$2:$G$251,MATCH($A37,'Raw Data'!$F$2:$F$251,0)) -> Electronics | J37: =IF(ISNUMBER(FIND(" ",$A37)),UPPER(LEFT($A37,1)&MID($A37,FIND(" ",$A37)+1,1)),UPPER(LEFT($A37,3))) -> LAP | K37: =RANK(C37,$C$37:$C$46,0) -> 7
A38: Smartphone | B38: =SUMIFS('Raw Data'!$N$2:$N$251,'Raw Data'!$F$2:$F$251,$A38) -> 67199.04 | C38: =COUNTIFS('Raw Data'!$F$2:$F$251,$A38) -> 31 | D38: =SUMIFS('Raw Data'!$H$2:$H$251,'Raw Data'!$F$2:$F$251,$A38) -> 96 | E38: =IFERROR(B38/C38,0) -> 2167.711 | F38: =B38/$B$47 -> 0.29319916 | G38: =RANK(B38,$B$37:$B$46,0) -> 2 | H38: =INDEX('Raw Data'!$E$2:$E$251,MATCH($A38,'Raw Data'!$F$2:$F$251,0)) -> P002 | I38: =INDEX('Raw Data'!$G$2:$G$251,MATCH($A38,'Raw Data'!$F$2:$F$251,0)) -> Electronics | J38: =IF(ISNUMBER(FIND(" ",$A38)),UPPER(LEFT($A38,1)&MID($A38,FIND(" ",$A38)+1,1)),UPPER(LEFT($A38,3))) -> SMA | K38: =RANK(C38,$C$37:$C$46,0) -> 3
A39: Headphones | B39: =SUMIFS('Raw Data'!$N$2:$N$251,'Raw Data'!$F$2:$F$251,$A39) -> 7049.53 | C39: =COUNTIFS('Raw Data'!$F$2:$F$251,$A39) -> 16 | D39: =SUMIFS('Raw Data'!$H$2:$H$251,'Raw Data'!$F$2:$F$251,$A39) -> 47 | E39: =IFERROR(B39/C39,0) -> 440.59562 | F39: =B39/$B$47 -> 0.030758122 | G39: =RANK(B39,$B$37:$B$46,0) -> 8 | H39: =INDEX('Raw Data'!$E$2:$E$251,MATCH($A39,'Raw Data'!$F$2:$F$251,0)) -> P003 | I39: =INDEX('Raw Data'!$G$2:$G$251,MATCH($A39,'Raw Data'!$F$2:$F$251,0)) -> Electronics | J39: =IF(ISNUMBER(FIND(" ",$A39)),UPPER(LEFT($A39,1)&MID($A39,FIND(" ",$A39)+1,1)),UPPER(LEFT($A39,3))) -> HEA | K39: =RANK(C39,$C$37:$C$46,0) -> 8
A40: Coffee Maker | B40: =SUMIFS('Raw Data'!$N$2:$N$251,'Raw Data'!$F$2:$F$251,$A40) -> 3119.61 | C40: =COUNTIFS('Raw Data'!$F$2:$F$251,$A40) -> 14 | D40: =SUMIFS('Raw Data'!$H$2:$H$251,'Raw Data'!$F$2:$F$251,$A40) -> 39 | E40: =IFERROR(B40/C40,0) -> 222.82929 | F40: =B40/$B$47 -> 0.013611311 | G40: =RANK(B40,$B$37:$B$46,0) -> 10 | H40: =INDEX('Raw Data'!$E$2:$E$251,MATCH($A40,'Raw Data'!$F$2:$F$251,0)) -> P004 | I40: =INDEX('Raw Data'!$G$2:$G$251,MATCH($A40,'Raw Data'!$F$2:$F$251,0)) -> Appliances | J40: =IF(ISNUMBER(FIND(" ",$A40)),UPPER(LEFT($A40,1)&MID($A40,FIND(" ",$A40)+1,1)),UPPER(LEFT($A40,3))) -> CM | K40: =RANK(C40,$C$37:$C$46,0) -> 10
A41: Blender | B41: =SUMIFS('Raw Data'!$N$2:$N$251,'Raw Data'!$F$2:$F$251,$A41) -> 5219.13 | C41: =COUNTIFS('Raw Data'!$F$2:$F$251,$A41) -> 29 | D41: =SUMIFS('Raw Data'!$H$2:$H$251,'Raw Data'!$F$2:$F$251,$A41) -> 87 | E41: =IFERROR(B41/C41,0) -> 179.97 | F41: =B41/$B$47 -> 0.022771821 | G41: =RANK(B41,$B$37:$B$46,0) -> 9 | H41: =INDEX('Raw Data'!$E$2:$E$251,MATCH($A41,'Raw Data'!$F$2:$F$251,0)) -> P005 | I41: =INDEX('Raw Data'!$G$2:$G$251,MATCH($A41,'Raw Data'!$F$2:$F$251,0)) -> Appliances | J41: =IF(ISNUMBER(FIND(" ",$A41)),UPPER(LEFT($A41,1)&MID($A41,FIND(" ",$A41)+1,1)),UPPER(LEFT($A41,3))) -> BLE | K41: =RANK(C41,$C$37:$C$46,0) -> 4
A42: Office Chair | B42: =SUMIFS('Raw Data'!$N$2:$N$251,'Raw Data'!$F$2:$F$251,$A42) -> 10399.48 | C42: =COUNTIFS('Raw Data'!$F$2:$F$251,$A42) -> 15 | D42: =SUMIFS('Raw Data'!$H$2:$H$251,'Raw Data'!$F$2:$F$251,$A42) -> 52 | E42: =IFERROR(B42/C42,0) -> 693.29867 | F42: =B42/$B$47 -> 0.04537444 | G42: =RANK(B42,$B$37:$B$46,0) -> 6 | H42: =INDEX('Raw Data'!$E$2:$E$251,MATCH($A42,'Raw Data'!$F$2:$F$251,0)) -> P006 | I42: =INDEX('Raw Data'!$G$2:$G$251,MATCH($A42,'Raw Data'!$F$2:$F$251,0)) -> Furniture | J42: =IF(ISNUMBER(FIND(" ",$A42)),UPPER(LEFT($A42,1)&MID($A42,FIND(" ",$A42)+1,1)),UPPER(LEFT($A42,3))) -> OC | K42: =RANK(C42,$C$37:$C$46,0) -> 9
A43: Desk | B43: =SUMIFS('Raw Data'!$N$2:$N$251,'Raw Data'!$F$2:$F$251,$A43) -> 23399.22 | C43: =COUNTIFS('Raw Data'!$F$2:$F$251,$A43) -> 26 | D43: =SUMIFS('Raw Data'!$H$2:$H$251,'Raw Data'!$F$2:$F$251,$A43) -> 78 | E43: =IFERROR(B43/C43,0) -> 899.97 | F43: =B43/$B$47 -> 0.10209419 | G43: =RANK(B43,$B$37:$B$46,0) -> 3 | H43: =INDEX('Raw Data'!$E$2:$E$251,MATCH($A43,'Raw Data'!$F$2:$F$251,0)) -> P007 | I43: =INDEX('Raw Data'!$G$2:$G$251,MATCH($A43,'Raw Data'!$F$2:$F$251,0)) -> Furniture | J43: =IF(ISNUMBER(FIND(" ",$A43)),UPPER(LEFT($A43,1)&MID($A43,FIND(" ",$A43)+1,1)),UPPER(LEFT($A43,3))) -> DES | K43: =RANK(C43,$C$37:$C$46,0) -> 5
A44: Bookshelf | B44: =SUMIFS('Raw Data'!$N$2:$N$251,'Raw Data'!$F$2:$F$251,$A44) -> 15298.98 | C44: =COUNTIFS('Raw Data'!$F$2:$F$251,$A44) -> 35 | D44: =SUMIFS('Raw Data'!$H$2:$H$251,'Raw Data'!$F$2:$F$251,$A44) -> 102 | E44: =IFERROR(B44/C44,0) -> 437.11371 | F44: =B44/$B$47 -> 0.066751669 | G44: =RANK(B44,$B$37:$B$46,0) -> 5 | H44: =INDEX('Raw Data'!$E$2:$E$251,MATCH($A44,'Raw Data'!$F$2:$F$251,0)) -> P008 | I44: =INDEX('Raw Data'!$G$2:$G$251,MATCH($A44,'Raw Data'!$F$2:$F$251,0)) -> Furniture | J44: =IF(ISNUMBER(FIND(" ",$A44)),UPPER(LEFT($A44,1)&MID($A44,FIND(" ",$A44)+1,1)),UPPER(LEFT($A44,3))) -> BOO | K44: =RANK(C44,$C$37:$C$46,0) -> 1
A45: Monitor | B45: =SUMIFS('Raw Data'!$N$2:$N$251,'Raw Data'!$F$2:$F$251,$A45) -> 21999.12 | C45: =COUNTIFS('Raw Data'!$F$2:$F$251,$A45) -> 26 | D45: =SUMIFS('Raw Data'!$H$2:$H$251,'Raw Data'!$F$2:$F$251,$A45) -> 88 | E45: =IFERROR(B45/C45,0) -> 846.12 | F45: =B45/$B$47 -> 0.095985352 | G45: =RANK(B45,$B$37:$B$46,0) -> 4 | H45: =INDEX('Raw Data'!$E$2:$E$251,MATCH($A45,'Raw Data'!$F$2:$F$251,0)) -> P009 | I45: =INDEX('Raw Data'!$G$2:$G$251,MATCH($A45,'Raw Data'!$F$2:$F$251,0)) -> Electronics | J45: =IF(ISNUMBER(FIND(" ",$A45)),UPPER(LEFT($A45,1)&MID($A45,FIND(" ",$A45)+1,1)),UPPER(LEFT($A45,3))) -> MON | K45: =RANK(C45,$C$37:$C$46,0) -> 5
A46: Keyboard | B46: =SUMIFS('Raw Data'!$N$2:$N$251,'Raw Data'!$F$2:$F$251,$A46) -> 8009.11 | C46: =COUNTIFS('Raw Data'!$F$2:$F$251,$A46) -> 34 | D46: =SUMIFS('Raw Data'!$H$2:$H$251,'Raw Data'!$F$2:$F$251,$A46) -> 89 | E46: =IFERROR(B46/C46,0) -> 235.56206 | F46: =B46/$B$47 -> 0.034944909 | G46: =RANK(B46,$B$37:$B$46,0) -> 7 | H46: =INDEX('Raw Data'!$E$2:$E$251,MATCH($A46,'Raw Data'!$F$2:$F$251,0)) -> P010 | I46: =INDEX('Raw Data'!$G$2:$G$251,MATCH($A46,'Raw Data'!$F$2:$F$251,0)) -> Electronics | J46: =IF(ISNUMBER(FIND(" ",$A46)),UPPER(LEFT($A46,1)&MID($A46,FIND(" ",$A46)+1,1)),UPPER(LEFT($A46,3))) -> KEY | K46: =RANK(C46,$C$37:$C$46,0) -> 2
...

Sheet Customer Analysis
A1: Customer Analysis - GroupBy & High-Value Customers
A3: High-Value percentile cut-off | B3: 0.8 | D3: High-Value customers | E3: =COUNTIF($P$23:$P$72,"High-Value") -> 10 | G3: Repeat customers (2+ orders) | H3: =COUNTIF($Q$23:$Q$72,"Repeat") -> 47
A4: High-Value revenue threshold | B4: =PERCENTILE($G$23:$G$72,B3) -> 6557.8 | D4: Revenue from High-Value | E4: =SUMIF($P$23:$P$72,"High-Value",$G$23:$G$72) -> 93867.66 | G4: Repeat customer rate | H4: =H3/COUNTA($A$23:$A$72) -> 0.94
A5: H1 / H2 split date (mid-point of data) | B5: =MIN('Raw Data'!$B$2:$B$251)+ROUND((MAX('Raw Data'!$B$2:$B$251)-MIN('Raw Data'!$B$2:$B$251))/2,0) -> 45576 | D5: % of total revenue | E5: =E4/SUM($G$23:$G$72) -> 0.40955822 | G5: Customers with conflicting "Since" dates | H5: =COUNTIF($M$23:$M$72,"Yes") -> 47
A7: Top 10 Customers by Revenue
A8: Rank | B8: Customer ID | C8: Customer Name | D8: Revenue | E8: Orders | F8: % of Total Revenue | G8: Cumulative % | H8: Tier
A9: 1 | B9: =INDEX($A$23:$A$72,MATCH($A9,$O$23:$O$72,0)) -> CUST025 | C9: =INDEX($B$23:$B$72,MATCH($A9,$O$23:$O$72,0)) -> Mark Carter | D9: =INDEX($G$23:$G$72,MATCH($A9,$O$23:$O$72,0)) -> 15659.65 | E9: =INDEX($E$23:$E$72,MATCH($A9,$O$23:$O$72,0)) -> 12 | F9: =D9/'Sales Analysis'!$B$11 -> 0.068325325 | G9: =SUM($F$9:F9) -> 0.068325325 | H9: =INDEX($P$23:$P$72,MATCH($A9,$O$23:$O$72,0)) -> High-Value
A10: 2 | B10: =INDEX($A$23:$A$72,MATCH($A10,$O$23:$O$72,0)) -> CUST029 | C10: =INDEX($B$23:$B$72,MATCH($A10,$O$23:$O$72,0)) -> Edward Mitchell | D10: =INDEX($G$23:$G$72,MATCH($A10,$O$23:$O$72,0)) -> 11919.77 | E10: =INDEX($E$23:$E$72,MATCH($A10,$O$23:$O$72,0)) -> 6 | F10: =D10/'Sales Analysis'!$B$11 -> 0.052007686 | G10: =SUM($F$9:F10) -> 0.12033301 | H10: =INDEX($P$23:$P$72,MATCH($A10,$O$23:$O$72,0)) -> High-Value
A11: 3 | B11: =INDEX($A$23:$A$72,MATCH($A11,$O$23:$O$72,0)) -> CUST018 | C11: =INDEX($B$23:$B$72,MATCH($A11,$O$23:$O$72,0)) -> Barbara Young | D11: =INDEX($G$23:$G$72,MATCH($A11,$O$23:$O$72,0)) -> 10649.8 | E11: =INDEX($E$23:$E$72,MATCH($A11,$O$23:$O$72,0)) -> 5 | F11: =D11/'Sales Analysis'!$B$11 -> 0.046466623 | G11: =SUM($F$9:F11) -> 0.16679963 | H11: =INDEX($P$23:$P$72,MATCH($A11,$O$23:$O$72,0)) -> High-Value
A12: 4 | B12: =INDEX($A$23:$A$72,MATCH($A12,$O$23:$O$72,0)) -> CUST012 | C12: =INDEX($B$23:$B$72,MATCH($A12,$O$23:$O$72,0)) -> Patricia Moore | D12: =INDEX($G$23:$G$72,MATCH($A12,$O$23:$O$72,0)) -> 9799.73 | E12: =INDEX($E$23:$E$72,MATCH($A12,$O$23:$O$72,0)) -> 8 | F12: =D12/'Sales Analysis'!$B$11 -> 0.042757644 | G12: =SUM($F$9:F12) -> 0.20955728 | H12: =INDEX($P$23:$P$72,MATCH($A12,$O$23:$O$72,0)) -> High-Value
A13: 5 | B13: =INDEX($A$23:$A$72,MATCH($A13,$O$23:$O$72,0)) -> CUST023 | C13: =INDEX($B$23:$B$72,MATCH($A13,$O$23:$O$72,0)) -> Paul Baker | D13: =INDEX($G$23:$G$72,MATCH($A13,$O$23:$O$72,0)) -> 8309.74 | E13: =INDEX($E$23:$E$72,MATCH($A13,$O$23:$O$72,0)) -> 8 | F13: =D13/'Sales Analysis'!$B$11 -> 0.036256601 | G13: =SUM($F$9:F13) -> 0.24581388 | H13: =INDEX($P$23:$P$72,MATCH($A13,$O$23:$O$72,0)) -> High-Value
A14: 6 | B14: =INDEX($A$23:$A$72,MATCH($A14,$O$23:$O$72,0)) -> CUST024 | C14: =INDEX($B$23:$B$72,MATCH($A14,$O$23:$O$72,0)) -> Dorothy Nelson | D14: =INDEX($G$23:$G$72,MATCH($A14,$O$23:$O$72,0)) -> 8269.79 | E14: =INDEX($E$23:$E$72,MATCH($A14,$O$23:$O$72,0)) -> 6 | F14: =D14/'Sales Analysis'!$B$11 -> 0.036082294 | G14: =SUM($F$9:F14) -> 0.28189617 | H14: =INDEX($P$23:$P$72,MATCH($A14,$O$23:$O$72,0)) -> High-Value
A15: 7 | B15: =INDEX($A$23:$A$72,MATCH($A15,$O$23:$O$72,0)) -> CUST026 | C15: =INDEX($B$23:$B$72,MATCH($A15,$O$23:$O$72,0)) -> Karen Hill | D15: =INDEX($G$23:$G$72,MATCH($A15,$O$23:$O$72,0)) -> 8009.77 | E15: =INDEX($E$23:$E$72,MATCH($A15,$O$23:$O$72,0)) -> 8 | F15: =D15/'Sales Analysis'!$B$11 -> 0.034947789 | G15: =SUM($F$9:F15) -> 0.31684396 | H15: =INDEX($P$23:$P$72,MATCH($A15,$O$23:$O$72,0)) -> High-Value
A16: 8 | B16: =INDEX($A$23:$A$72,MATCH($A16,$O$23:$O$72,0)) -> CUST019 | C16: =INDEX($B$23:$B$72,MATCH($A16,$O$23:$O$72,0)) -> Daniel King | D16: =INDEX($G$23:$G$72,MATCH($A16,$O$23:$O$72,0)) -> 7309.8 | E16: =INDEX($E$23:$E$72,MATCH($A16,$O$23:$O$72,0)) -> 7 | F16: =D16/'Sales Analysis'!$B$11 -> 0.031893718 | G16: =SUM($F$9:F16) -> 0.34873768 | H16: =INDEX($P$23:$P$72,MATCH($A16,$O$23:$O$72,0)) -> High-Value
A17: 9 | B17: =INDEX($A$23:$A$72,MATCH($A17,$O$23:$O$72,0)) -> CUST039 | C17: =INDEX($B$23:$B$72,MATCH($A17,$O$23:$O$72,0)) -> Lawrence Reed | D17: =INDEX($G$23:$G$72,MATCH($A17,$O$23:$O$72,0)) -> 6989.77 | E17: =INDEX($E$23:$E$72,MATCH($A17,$O$23:$O$72,0)) -> 8 | F17: =D17/'Sales Analysis'!$B$11 -> 0.030497381 | G17: =SUM($F$9:F17) -> 0.37923506 | H17: =INDEX($P$23:$P$72,MATCH($A17,$O$23:$O$72,0)) -> High-Value
A18: 10 | B18: =INDEX($A$23:$A$72,MATCH($A18,$O$23:$O$72,0)) -> CUST013 | C18: =INDEX($B$23:$B$72,MATCH($A18,$O$23:$O$72,0)) -> Joseph Jackson | D18: =INDEX($G$23:$G$72,MATCH($A18,$O$23:$O$72,0)) -> 6949.84 | E18: =INDEX($E$23:$E$72,MATCH($A18,$O$23:$O$72,0)) -> 5 | F18: =D18/'Sales Analysis'!$B$11 -> 0.03032316 | G18: =SUM($F$9:F18) -> 0.40955822 | H18: =INDEX($P$23:$P$72,MATCH($A18,$O$23:$O$72,0)) -> High-Value
A19: Top 10 | D19: =SUM(D9:D18) -> 93867.66 | E19: =SUM(E9:E18) -> 73 | F19: =SUM(F9:F18) -> 0.40955822
A21: Customer Master (one row per customer) - GroupBy by Customer_ID
A22: Customer ID | B22: Customer Name | C22: Initials | D22: Short Code | E22: Orders | F22: Units | G22: Revenue | H22: Avg Order Value | I22: First Purchase | J22: Last Purchase | K22: Customer Since (earliest) | L22: Tenure (Yrs, to TODAY) | M22: Since-date Conflict? | N22: Revenue Rank | O22: Unique Rank (tie-break) | P22: Value Tier | Q22: Repeat? | R22: Orders Unique Rank | S22: Active H1 | T22: Active H2 | U22: H1 Seq | V22: H2 Seq | W22: Days Since Last Purchase
A23: CUST001 | B23: =INDEX('Raw Data'!$D$2:$D$251,MATCH($A23,'Raw Data'!$C$2:$C$251,0)) -> John Smith | C23: =UPPER(LEFT(B23,1)&MID(B23,FIND(" ",B23)+1,1)) -> JS | D23: =UPPER(LEFT(B23,1)&MID(B23,FIND(" ",B23)+1,3))&"-"&TEXT(VALUE(RIGHT(A23,3)),"000") -> JSMI-001 | E23: =COUNTIF('Raw Data'!$C$2:$C$251,$A23) -> 1 | F23: =SUMIF('Raw Data'!$C$2:$C$251,$A23,'Raw Data'!$H$2:$H$251) -> 4 | G23: =SUMIF('Raw Data'!$C$2:$C$251,$A23,'Raw Data'!$N$2:$N$251) -> 599.96 | H23: =IFERROR(G23/E23,0) -> 599.96 | I23: =_xlfn.MINIFS('Raw Data'!$B$2:$B$251,'Raw Data'!$C$2:$C$251,$A23) -> 45740 | J23: =_xlfn.MAXIFS('Raw Data'!$B$2:$B$251,'Raw Data'!$C$2:$C$251,$A23) -> 45740 | K23: =_xlfn.MINIFS('Raw Data'!$M$2:$M$251,'Raw Data'!$C$2:$C$251,$A23) -> 44560 | L23: =DATEDIF(K23,TODAY(),"Y") -> 4 | M23: =IF(_xlfn.MAXIFS('Raw Data'!$M$2:$M$251,'Raw Data'!$C$2:$C$251,$A23)-_xlfn.MINIFS('Raw Data'!$M$2:$M$251,'Raw Data'!$C$2:$C$251,$A23)>0,"Yes","No") -> No | N23: =RANK(G23,$G$23:$G$72,0) -> 47 | O23: =N23+COUNTIF($N$23:N23,N23)-1 -> 47 | P23: =IF(G23>=$B$4,"High-Value","Standard") -> Standard | Q23: =IF(E23>1,"Repeat","One-time") -> One-time | R23: =RANK(E23,$E$23:$E$72,0)+COUNTIF($E$23:E23,E23)-1 -> 48 | S23: =IF(COUNTIFS('Raw Data'!$C$2:$C$251,$A23,'Raw Data'!$B$2:$B$251,"<="&$B$5)>0,1,0) -> 0 | T23: =IF(COUNTIFS('Raw Data'!$C$2:$C$251,$A23,'Raw Data'!$B$2:$B$251,">"&$B$5)>0,1,0) -> 1 | U23: =IF(S23=1,SUM($S$23:S23),"") | V23: =IF(T23=1,SUM($T$23:T23),"") -> 1 | W23: =TODAY()-J23 -> 570
A24: CUST002 | B24: =INDEX('Raw Data'!$D$2:$D$251,MATCH($A24,'Raw Data'!$C$2:$C$251,0)) -> Emma Wilson | C24: =UPPER(LEFT(B24,1)&MID(B24,FIND(" ",B24)+1,1)) -> EW | D24: =UPPER(LEFT(B24,1)&MID(B24,FIND(" ",B24)+1,3))&"-"&TEXT(VALUE(RIGHT(A24,3)),"000") -> EWIL-002 | E24: =COUNTIF('Raw Data'!$C$2:$C$251,$A24) -> 5 | F24: =SUMIF('Raw Data'!$C$2:$C$251,$A24,'Raw Data'!$H$2:$H$251) -> 12 | G24: =SUMIF('Raw Data'!$C$2:$C$251,$A24,'Raw Data'!$N$2:$N$251) -> 1229.88 | H24: =IFERROR(G24/E24,0) -> 245.976 | I24: =_xlfn.MINIFS('Raw Data'!$B$2:$B$251,'Raw Data'!$C$2:$C$251,$A24) -> 45430 | J24: =_xlfn.MAXIFS('Raw Data'!$B$2:$B$251,'Raw Data'!$C$2:$C$251,$A24) -> 45737 | K24: =_xlfn.MINIFS('Raw Data'!$M$2:$M$251,'Raw Data'!$C$2:$C$251,$A24) -> 44748 | L24: =DATEDIF(K24,TODAY(),"Y") -> 4 | M24: =IF(_xlfn.MAXIFS('Raw Data'!$M$2:$M$251,'Raw Data'!$C$2:$C$251,$A24)-_xlfn.MINIFS('Raw Data'!$M$2:$M$251,'Raw Data'!$C$2:$C$251,$A24)>0,"Yes","No") -> Yes | N24: =RANK(G24,$G$23:$G$72,0) -> 44 | O24: =N24+COUNTIF($N$23:N24,N24)-1 -> 44 | P24: =IF(G24>=$B$4,"High-Value","Standard") -> Standard | Q24: =IF(E24>1,"Repeat","One-time") -> Repeat | R24: =RANK(E24,$E$23:$E$72,0)+COUNTIF($E$23:E24,E24)-1 -> 19 | S24: =IF(COUNTIFS('Raw Data'!$C$2:$C$251,$A24,'Raw Data'!$B$2:$B$251,"<="&$B$5)>0,1,0) -> 1 | T24: =IF(COUNTIFS('Raw Data'!$C$2:$C$251,$A24,'Raw Data'!$B$2:$B$251,">"&$B$5)>0,1,0) -> 1 | U24: =IF(S24=1,SUM($S$23:S24),"") -> 1 | V24: =IF(T24=1,SUM($T$23:T24),"") -> 2 | W24: =TODAY()-J24 -> 573
A25: CUST003 | B25: =INDEX('Raw Data'!$D$2:$D$251,MATCH($A25,'Raw Data'!$C$2:$C$251,0)) -> Michael Brown | C25: =UPPER(LEFT(B25,1)&MID(B25,FIND(" ",B25)+1,1)) -> MB | D25: =UPPER(LEFT(B25,1)&MID(B25,FIND(" ",B25)+1,3))&"-"&TEXT(VALUE(RIGHT(A25,3)),"000") -> MBRO-003 | E25: =COUNTIF('Raw Data'!$C$2:$C$251,$A25) -> 9 | F25: =SUMIF('Raw Data'!$C$2:$C$251,$A25,'Raw Data'!$H$2:$H$251) -> 26 | G25: =SUMIF('Raw Data'!$C$2:$C$251,$A25,'Raw Data'!$N$2:$N$251) -> 6169.74 | H25: =IFERROR(G25/E25,0) -> 685.52667 | I25: =_xlfn.MINIFS('Raw Data'!$B$2:$B$251,'Raw Data'!$C$2:$C$251,$A25) -> 45400 | J25: =_xlfn.MAXIFS('Raw Data'!$B$2:$B$251,'Raw Data'!$C$2:$C$251,$A25) -> 45707 | K25: =_xlfn.MINIFS('Raw Data'!$M$2:$M$251,'Raw Data'!$C$2:$C$251,$A25) -> 44422 | L25: =DATEDIF(K25,TODAY(),"Y") -> 5 | M25: =IF(_xlfn.MAXIFS('Raw Data'!$M$2:$M$251,'Raw Data'!$C$2:$C$251,$A25)-_xlfn.MINIFS('Raw Data'!$M$2:$M$251,'Raw Data'!$C$2:$C$251,$A25)>0,"Yes","No") -> Yes | N25: =RANK(G25,$G$23:$G$72,0) -> 14 | O25: =N25+COUNTIF($N$23:N25,N25)-1 -> 14 | P25: =IF(G25>=$B$4,"High-Value","Standard") -> Standard | Q25: =IF(E25>1,"Repeat","One-time") -> Repeat | R25: =RANK(E25,$E$23:$E$72,0)+COUNTIF($E$23:E25,E25)-1 -> 2 | S25: =IF(COUNTIFS('Raw Data'!$C$2:$C$251,$A25,'Raw Data'!$B$2:$B$251,"<="&$B$5)>0,1,0) -> 1 | T25: =IF(COUNTIFS('Raw Data'!$C$2:$C$251,$A25,'Raw Data'!$B$2:$B$251,">"&$B$5)>0,1,0) -> 1 | U25: =IF(S25=1,SUM($S$23:S25),"") -> 2 | V25: =IF(T25=1,SUM($T$23:T25),"") -> 3 | W25: =TODAY()-J25 -> 603
A26: CUST004 | B26: =INDEX('Raw Data'!$D$2:$D$251,MATCH($A26,'Raw Data'!$C$2:$C$251,0)) -> Sarah Davis | C26: =UPPER(LEFT(B26,1)&MID(B26,FIND(" ",B26)+1,1)) -> SD | D26: =UPPER(LEFT(B26,1)&MID(B26,FIND(" ",B26)+1,3))&"-"&TEXT(VALUE(RIGHT(A26,3)),"000") -> SDAV-004 | E26: =COUNTIF('Raw Data'!$C$2:$C$251,$A26) -> 5 | F26: =SUMIF('Raw Data'!$C$2:$C$251,$A26,'Raw Data'!$H$2:$H$251) -> 19 | G26: =SUMIF('Raw Data'!$C$2:$C$251,$A26,'Raw Data'!$N$2:$N$251) -> 5499.81 | H26: =IFERROR(G26/E26,0) -> 1099.962 | I26: =_xlfn.MINIFS('Raw Data'!$B$2:$B$251,'Raw Data'!$C$2:$C$251,$A26) -> 45446 | J26: =_xlfn.MAXIFS('Raw Data'!$B$2:$B$251,'Raw Data'!$C$2:$C$251,$A26) -> 45619 | K26: =_xlfn.MINIFS('Raw Data'!$M$2:$M$251,'Raw Data'!$C$2:$C$251,$A26) -> 44458 | L26: =DATEDIF(K26,TODAY(),"Y") -> 5 | M26: =IF(_xlfn.MAXIFS('Raw Data'!$M$2:$M$251,'Raw Data'!$C$2:$C$251,$A26)-_xlfn.MINIFS('Raw Data'!$M$2:$M$251,'Raw Data'!$C$2:$C$251,$A26)>0,"Yes","No") -> Yes | N26: =RANK(G26,$G$23:$G$72,0) -> 19 | O26: =N26+COUNTIF($N$23:N26,N26)-1 -> 19 | P26: =IF(G26>=$B$4,"High-Value","Standard") -> Standard | Q26: =IF(E26>1,"Repeat","One-time") -> Repeat | R26: =RANK(E26,$E$23:$E$72,0)+COUNTIF($E$23:E26,E26)-1 -> 20 | S26: =IF(COUNTIFS('Raw Data'!$C$2:$C$251,$A26,'Raw Data'!$B$2:$B$251,"<="&$B$5)>0,1,0) -> 1 | T26: =IF(COUNTIFS('Raw Data'!$C$2:$C$251,$A26,'Raw Data'!$B$2:$B$251,">"&$B$5)>0,1,0) -> 1 | U26: =IF(S26=1,SUM($S$23:S26),"") -> 3 | V26: =IF(T26=1,SUM($T$23:T26),"") -> 4 | W26: =TODAY()-J26 -> 691
A27: CUST005 | B27: =INDEX('Raw Data'!$D$2:$D$251,MATCH($A27,'Raw Data'!$C$2:$C$251,0)) -> James Johnson | C27: =UPPER(LEFT(B27,1)&MID(B27,FIND(" ",B27)+1,1)) -> JJ | D27: =UPPER(LEFT(B27,1)&MID(B27,FIND(" ",B27)+1,3))&"-"&TEXT(VALUE(RIGHT(A27,3)),"000") -> JJOH-005 | E27: =COUNTIF('Raw Data'!$C$2:$C$251,$A27) -> 1 | F27: =SUMIF('Raw Data'!$C$2:$C$251,$A27,'Raw Data'!$H$2:$H$251) -> 3 | G27: =SUMIF('Raw Data'!$C$2:$C$251,$A27,'Raw Data'!$N$2:$N$251) -> 179.97 | H27: =IFERROR(G27/E27,0) -> 179.97 | I27: =_xlfn.MINIFS('Raw Data'!$B$2:$B$251,'Raw Data'!$C$2:$C$251,$A27) -> 45635 | J27: =_xlfn.MAXIFS('Raw Data'!$B$2:$B$251,'Raw Data'!$C$2:$C$251,$A27) -> 45635 | K27: =_xlfn.MINIFS('Raw Data'!$M$2:$M$251,'Raw Data'!$C$2:$C$251,$A27) -> 45052 | L27: =DATEDIF(K27,TODAY(),"Y") -> 3 | M27: =IF(_xlfn.MAXIFS('Raw Data'!$M$2:$M$251,'Raw Data'!$C$2:$C$251,$A27)-_xlfn.MINIFS('Raw Data'!$M$2:$M$251,'Raw Data'!$C$2:$C$251,$A27)>0,"Yes","No") -> No | N27: =RANK(G27,$G$23:$G$72,0) -> 50 | O27: =N27+COUNTIF($N$23:N27,N27)-1 -> 50 | P27: =IF(G27>=$B$4,"High-Value","Standard") -> Standard | Q27: =IF(E27>1,"Repeat","One-time") -> One-time | R27: =RANK(E27,$E$23:$E$72,0)+COUNTIF($E$23:E27,E27)-1 -> 49 | S27: =IF(COUNTIFS('Raw Data'!$C$2:$C$251,$A27,'Raw Data'!$B$2:$B$251,"<="&$B$5)>0,1,0) -> 0 | T27: =IF(COUNTIFS('Raw Data'!$C$2:$C$251,$A27,'Raw Data'!$B$2:$B$251,">"&$B$5)>0,1,0) -> 1 | U27: =IF(S27=1,SUM($S$23:S27),"") | V27: =IF(T27=1,SUM($T$23:T27),"") -> 5 | W27: =TODAY()-J27 -> 675
A28: CUST006 | B28: =INDEX('Raw Data'!$D$2:$D$251,MATCH($A28,'Raw Data'!$C$2:$C$251,0)) -> Lisa Anderson | C28: =UPPER(LEFT(B28,1)&MID(B28,FIND(" ",B28)+1,1)) -> LA | D28: =UPPER(LEFT(B28,1)&MID(B28,FIND(" ",B28)+1,3))&"-"&TEXT(VALUE(RIGHT(A28,3)),"000") -> LAND-006 | E28: =COUNTIF('Raw Data'!$C$2:$C$251,$A28) -> 5 | F28: =SUMIF('Raw Data'!$C$2:$C$251,$A28,'Raw Data'!$H$2:$H$251) -> 20 | G28: =SUMIF('Raw Data'!$C$2:$C$251,$A28,'Raw Data'!$N$2:$N$251) -> 2039.8 | H28: =IFERROR(G28/E28,0) -> 407.96 | I28: =_xlfn.MINIFS('Raw Data'!$B$2:$B$251,'Raw Data'!$C$2:$C$251,$A28) -> 45428 | J28: =_xlfn.MAXIFS('Raw Data'!$B$2:$B$251,'Raw Data'!$C$2:$C$251,$A28) -> 45676 | K28: =_xlfn.MINIFS('Raw Data'!$M$2:$M$251,'Raw Data'!$C$2:$C$251,$A28) -> 44579 | L28: =DATEDIF(K28,TODAY(),"Y") -> 4 | M28: =IF(_xlfn.MAXIFS('Raw Data'!$M$2:$M$251,'Raw Data'!$C$2:$C$251,$A28)-_xlfn.MINIFS('Raw Data'!$M$2:$M$251,'Raw Data'!$C$2:$C$251,$A28)>0,"Yes","No") -> Yes | N28: =RANK(G28,$G$23:$G$72,0) -> 36 | O28: =N28+COUNTIF($N$23:N28,N28)-1 -> 36 | P28: =IF(G28>=$B$4,"High-Value","Standard") -> Standard | Q28: =IF(E28>1,"Repeat","One-time") -> Repeat | R28: =RANK(E28,$E$23:$E$72,0)+COUNTIF($E$23:E28,E28)-1 -> 21 | S28: =IF(COUNTIFS('Raw Data'!$C$2:$C$251,$A28,'Raw Data'!$B$2:$B$251,"<="&$B$5)>0,1,0) -> 1 | T28: =IF(COUNTIFS('Raw Data'!$C$2:$C$251,$A28,'Raw Data'!$B$2:$B$251,">"&$B$5)>0,1,0) -> 1 | U28: =IF(S28=1,SUM($S$23:S28),"") -> 4 | V28: =IF(T28=1,SUM($T$23:T28),"") -> 6 | W28: =TODAY()-J28 -> 634
A29: CUST007 | B29: =INDEX('Raw Data'!$D$2:$D$251,MATCH($A29,'Raw Data'!$C$2:$C$251,0)) -> David Martinez | C29: =UPPER(LEFT(B29,1)&MID(B29,FIND(" ",B29)+1,1)) -> DM | D29: =UPPER(LEFT(B29,1)&MID(B29,FIND(" ",B29)+1,3))&"-"&TEXT(VALUE(RIGHT(A29,3)),"000") -> DMAR-007 | E29: =COUNTIF('Raw Data'!$C$2:$C$251,$A29) -> 6 | F29: =SUMIF('Raw Data'!$C$2:$C$251,$A29,'Raw Data'!$H$2:$H$251) -> 16 | G29: =SUMIF('Raw Data'!$C$2:$C$251,$A29,'Raw Data'!$N$2:$N$251) -> 1809.84 | H29: =IFERROR(G29/E29,0) -> 301.64 | I29: =_xlfn.MINIFS('Raw Data'!$B$2:$B$251,'Raw Data'!$C$2:$C$251,$A29) -> 45476 | J29: =_xlfn.MAXIFS('Raw Data'!$B$2:$B$251,'Raw Data'!$C$2:$C$251,$A29) -> 45648 | K29: =_xlfn.MINIFS('Raw Data'!$M$2:$M$251,'Raw Data'!$C$2:$C$251,$A29) -> 44522 | L29: =DATEDIF(K29,TODAY(),"Y") -> 4 | M29: =IF(_xlfn.MAXIFS('Raw Data'!$M$2:$M$251,'Raw Data'!$C$2:$C$251,$A29)-_xlfn.MINIFS('Raw Data'!$M$2:$M$251,'Raw Data'!$C$2:$C$251,$A29)>0,"Yes","No") -> Yes | N29: =RANK(G29,$G$23:$G$72,0) -> 39 | O29: =N29+COUNTIF($N$23:N29,N29)-1 -> 39 | P29: =IF(G29>=$B$4,"High-Value","Standard") -> Standard | Q29: =IF(E29>1,"Repeat","One-time") -> Repeat | R29: =RANK(E29,$E$23:$E$72,0)+COUNTIF($E$23:E29,E29)-1 -> 10 | S29: =IF(COUNTIFS('Raw Data'!$C$2:$C$251,$A29,'Raw Data'!$B$2:$B$251,"<="&$B$5)>0,1,0) -> 1 | T29: =IF(COUNTIFS('Raw Data'!$C$2:$C$251,$A29,'Raw Data'!$B$2:$B$251,">"&$B$5)>0,1,0) -> 1 | U29: =IF(S29=1,SUM($S$23:S29),"") -> 5 | V29: =IF(T29=1,SUM($T$23:T29),"") -> 7 | W29: =TODAY()-J29 -> 662
A30: CUST008 | B30: =INDEX('Raw Data'!$D$2:$D$251,MATCH($A30,'Raw Data'!$C$2:$C$251,0)) -> Jennifer Taylor | C30: =UPPER(LEFT(B30,1)&MID(B30,FIND(" ",B30)+1,1)) -> JT | D30: =UPPER(LEFT(B30,1)&MID(B30,FIND(" ",B30)+1,3))&"-"&TEXT(VALUE(RIGHT(A30,3)),"000") -> JTAY-008 | E30: =COUNTIF('Raw Data'!$C$2:$C$251,$A30) -> 4 | F30: =SUMIF('Raw Data'!$C$2:$C$251,$A30,'Raw Data'!$H$2:$H$251) -> 15 | G30: =SUMIF('Raw Data'!$C$2:$C$251,$A30,'Raw Data'!$N$2:$N$251) -> 4739.85 | H30: =IFERROR(G30/E30,0) -> 1184.9625 | I30: =_xlfn.MINIFS('Raw Data'!$B$2:$B$251,'Raw Data'!$C$2:$C$251,$A30) -> 45440 | J30: =_xlfn.MAXIFS('Raw Data'!$B$2:$B$251,'Raw Data'!$C$2:$C$251,$A30) -> 45635 | K30: =_xlfn.MINIFS('Raw Data'!$M$2:$M$251,'Raw Data'!$C$2:$C$251,$A30) -> 44407 | L30: =DATEDIF(K30,TODAY(),"Y") -> 5 | M30: =IF(_xlfn.MAXIFS('Raw Data'!$M$2:$M$251,'Raw Data'!$C$2:$C$251,$A30)-_xlfn.MINIFS('Raw Data'!$M$2:$M$251,'Raw Data'!$C$2:$C$251,$A30)>0,"Yes","No") -> Yes | N30: =RANK(G30,$G$23:$G$72,0) -> 24 | O30: =N30+COUNTIF($N$23:N30,N30)-1 -> 24 | P30: =IF(G30>=$B$4,"High-Value","Standard") -> Standard | Q30: =IF(E30>1,"Repeat","One-time") -> Repeat | R30: =RANK(E30,$E$23:$E$72,0)+COUNTIF($E$23:E30,E30)-1 -> 30 | S30: =IF(COUNTIFS('Raw Data'!$C$2:$C$251,$A30,'Raw Data'!$B$2:$B$251,"<="&$B$5)>0,1,0) -> 1 | T30: =IF(COUNTIFS('Raw Data'!$C$2:$C$251,$A30,'Raw Data'!$B$2:$B$251,">"&$B$5)>0,1,0) -> 1 | U30: =IF(S30=1,SUM($S$23:S30),"") -> 6 | V30: =IF(T30=1,SUM($T$23:T30),"") -> 8 | W30: =TODAY()-J30 -> 675
A31: CUST009 | B31: =INDEX('Raw Data'!$D$2:$D$251,MATCH($A31,'Raw Data'!$C$2:$C$251,0)) -> Robert Thomas | C31: =UPPER(LEFT(B31,1)&MID(B31,FIND(" ",B31)+1,1)) -> RT | D31: =UPPER(LEFT(B31,1)&MID(B31,FIND(" ",B31)+1,3))&"-"&TEXT(VALUE(RIGHT(A31,3)),"000") -> RTHO-009 | E31: =COUNTIF('Raw Data'!$C$2:$C$251,$A31) -> 5 | F31: =SUMIF('Raw Data'!$C$2:$C$251,$A31,'Raw Data'!$H$2:$H$251) -> 10 | G31: =SUMIF('Raw Data'!$C$2:$C$251,$A31,'Raw Data'!$N$2:$N$251) -> 3509.9 | H31: =IFERROR(G31/E31,0) -> 701.98 | I31: =_xlfn.MINIFS('Raw Data'!$B$2:$B$251,'Raw Data'!$C$2:$C$251,$A31) -> 45405 | J31: =_xlfn.MAXIFS('Raw Data'!$B$2:$B$251,'Raw Data'!$C$2:$C$251,$A31) -> 45756 | K31: =_xlfn.MINIFS('Raw Data'!$M$2:$M$251,'Raw Data'!$C$2:$C$251,$A31) -> 44395 | L31: =DATEDIF(K31,TODAY(),"Y") -> 5 | M31: =IF(_xlfn.MAXIFS('Raw Data'!$M$2:$M$251,'Raw Data'!$C$2:$C$251,$A31)-_xlfn.MINIFS('Raw Data'!$M$2:$M$251,'Raw Data'!$C$2:$C$251,$A31)>0,"Yes","No") -> Yes | N31: =RANK(G31,$G$23:$G$72,0) -> 32 | O31: =N31+COUNTIF($N$23:N31,N31)-1 -> 32 | P31: =IF(G31>=$B$4,"High-Value","Standard") -> Standard | Q31: =IF(E31>1,"Repeat","One-time") -> Repeat | R31: =RANK(E31,$E$23:$E$72,0)+COUNTIF($E$23:E31,E31)-1 -> 22 | S31: =IF(COUNTIFS('Raw Data'!$C$2:$C$251,$A31,'Raw Data'!$B$2:$B$251,"<="&$B$5)>0,1,0) -> 1 | T31: =IF(COUNTIFS('Raw Data'!$C$2:$C$251,$A31,'Raw Data'!$B$2:$B$251,">"&$B$5)>0,1,0) -> 1 | U31: =IF(S31=1,SUM($S$23:S31),"") -> 7 | V31: =IF(T31=1,SUM($T$23:T31),"") -> 9 | W31: =TODAY()-J31 -> 554
A32: CUST010 | B32: =INDEX('Raw Data'!$D$2:$D$251,MATCH($A32,'Raw Data'!$C$2:$C$251,0)) -> Maria Garcia | C32: =UPPER(LEFT(B32,1)&MID(B32,FIND(" ",B32)+1,1)) -> MG | D32: =UPPER(LEFT(B32,1)&MID(B32,FIND(" ",B32)+1,3))&"-"&TEXT(VALUE(RIGHT(A32,3)),"000") -> MGAR-010 | E32: =COUNTIF('Raw Data'!$C$2:$C$251,$A32) -> 4 | F32: =SUMIF('Raw Data'!$C$2:$C$251,$A32,'Raw Data'!$H$2:$H$251) -> 7 | G32: =SUMIF('Raw Data'!$C$2:$C$251,$A32,'Raw Data'!$N$2:$N$251) -> 1909.93 | H32: =IFERROR(G32/E32,0) -> 477.4825 | I32: =_xlfn.MINIFS('Raw Data'!$B$2:$B$251,'Raw Data'!$C$2:$C$251,$A32) -> 45410 | J32: =_xlfn.MAXIFS('Raw Data'!$B$2:$B$251,'Raw Data'!$C$2:$C$251,$A32) -> 45604 | K32: =_xlfn.MINIFS('Raw Data'!$M$2:$M$251,'Raw Data'!$C$2:$C$251,$A32) -> 44579 | L32: =DATEDIF(K32,TODAY(),"Y") -> 4 | M32: =IF(_xlfn.MAXIFS('Raw Data'!$M$2:$M$251,'Raw Data'!$C$2:$C$251,$A32)-_xlfn.MINIFS('Raw Data'!$M$2:$M$251,'Raw Data'!$C$2:$C$251,$A32)>0,"Yes","No") -> Yes | N32: =RANK(G32,$G$23:$G$72,0) -> 38 | O32: =N32+COUNTIF($N$23:N32,N32)-1 -> 38 | P32: =IF(G32>=$B$4,"High-Value","Standard") -> Standard | Q32: =IF(E32>1,"Repeat","One-time") -> Repeat | R32: =RANK(E32,$E$23:$E$72,0)+COUNTIF($E$23:E32,E32)-1 -> 31 | S32: =IF(COUNTIFS('Raw Data'!$C$2:$C$251,$A32,'Raw Data'!$B$2:$B$251,"<="&$B$5)>0,1,0) -> 1 | T32: =IF(COUNTIFS('Raw Data'!$C$2:$C$251,$A32,'Raw Data'!$B$2:$B$251,">"&$B$5)>0,1,0) -> 1 | U32: =IF(S32=1,SUM($S$23:S32),"") -> 8 | V32: =IF(T32=1,SUM($T$23:T32),"") -> 10 | W32: =TODAY()-J32 -> 706
A33: CUST011 | B33: =INDEX('Raw Data'!$D$2:$D$251,MATCH($A33,'Raw Data'!$C$2:$C$251,0)) -> William White | C33: =UPPER(LEFT(B33,1)&MID(B33,FIND(" ",B33)+1,1)) -> WW | D33: =UPPER(LEFT(B33,1)&MID(B33,FIND(" ",B33)+1,3))&"-"&TEXT(VALUE(RIGHT(A33,3)),"000") -> WWHI-011 | E33: =COUNTIF('Raw Data'!$C$2:$C$251,$A33) -> 3 | F33: =SUMIF('Raw Data'!$C$2:$C$251,$A33,'Raw Data'!$H$2:$H$251) -> 9 | G33: =SUMIF('Raw Data'!$C$2:$C$251,$A33,'Raw Data'!$N$2:$N$251) -> 4749.91 | H33: =IFERROR(G33/E33,0) -> 1583.3033 | I33: =_xlfn.MINIFS('Raw Data'!$B$2:$B$251,'Raw Data'!$C$2:$C$251,$A33) -> 45554 | J33: =_xlfn.MAXIFS('Raw Data'!$B$2:$B$251,'Raw Data'!$C$2:$C$251,$A33) -> 45686 | K33: =_xlfn.MINIFS('Raw Data'!$M$2:$M$251,'Raw Data'!$C$2:$C$251,$A33) -> 44482 | L33: =DATEDIF(K33,TODAY(),"Y") -> 5 | M33: =IF(_xlfn.MAXIFS('Raw Data'!$M$2:$M$251,'Raw Data'!$C$2:$C$251,$A33)-_xlfn.MINIFS('Raw Data'!$M$2:$M$251,'Raw Data'!$C$2:$C$251,$A33)>0,"Yes","No") -> Yes | N33: =RANK(G33,$G$23:$G$72,0) -> 23 | O33: =N33+COUNTIF($N$23:N33,N33)-1 -> 23 | P33: =IF(G33>=$B$4,"High-Value","Standard") -> Standard | Q33: =IF(E33>1,"Repeat","One-time") -> Repeat | R33: =RANK(E33,$E$23:$E$72,0)+COUNTIF($E$23:E33,E33)-1 -> 40 | S33: =IF(COUNTIFS('Raw Data'!$C$2:$C$251,$A33,'Raw Data'!$B$2:$B$251,"<="&$B$5)>0,1,0) -> 1 | T33: =IF(COUNTIFS('Raw Data'!$C$2:$C$251,$A33,'Raw Data'!$B$2:$B$251,">"&$B$5)>0,1,0) -> 1 | U33: =IF(S33=1,SUM($S$23:S33),"") -> 9 | V33: =IF(T33=1,SUM($T$23:T33),"") -> 11 | W33: =TODAY()-J33 -> 624
A34: CUST012 | B34: =INDEX('Raw Data'!$D$2:$D$251,MATCH($A34,'Raw Data'!$C$2:$C$251,0)) -> Patricia Moore | C34: =UPPER(LEFT(B34,1)&MID(B34,FIND(" ",B34)+1,1)) -> PM | D34: =UPPER(LEFT(B34,1)&MID(B34,FIND(" ",B34)+1,3))&"-"&TEXT(VALUE(RIGHT(A34,3)),"000") -> PMOO-012 | E34: =COUNTIF('Raw Data'!$C$2:$C$251,$A34) -> 8 | F34: =SUMIF('Raw Data'!$C$2:$C$251,$A34,'Raw Data'!$H$2:$H$251) -> 27 | G34: =SUMIF('Raw Data'!$C$2:$C$251,$A34,'Raw Data'!$N$2:$N$251) -> 9799.73 | H34: =IFERROR(G34/E34,0) -> 1224.9662 | I34: =_xlfn.MINIFS('Raw Data'!$B$2:$B$251,'Raw Data'!$C$2:$C$251,$A34) -> 45413 | J34: =_xlfn.MAXIFS('Raw Data'!$B$2:$B$251,'Raw Data'!$C$2:$C$251,$A34) -> 45607 | K34: =_xlfn.MINIFS('Raw Data'!$M$2:$M$251,'Raw Data'!$C$2:$C$251,$A34) -> 44409 | L34: =DATEDIF(K34,TODAY(),"Y") -> 5 | M34: =IF(_xlfn.MAXIFS('Raw Data'!$M$2:$M$251,'Raw Data'!$C$2:$C$251,$A34)-_xlfn.MINIFS('Raw Data'!$M$2:$M$251,'Raw Data'!$C$2:$C$251,$A34)>0,"Yes","No") -> Yes | N34: =RANK(G34,$G$23:$G$72,0) -> 4 | O34: =N34+COUNTIF($N$23:N34,N34)-1 -> 4 | P34: =IF(G34>=$B$4,"High-Value","Standard") -> High-Value | Q34: =IF(E34>1,"Repeat","One-time") -> Repeat | R34: =RANK(E34,$E$23:$E$72,0)+COUNTIF($E$23:E34,E34)-1 -> 4 | S34: =IF(COUNTIFS('Raw Data'!$C$2:$C$251,$A34,'Raw Data'!$B$2:$B$251,"<="&$B$5)>0,1,0) -> 1 | T34: =IF(COUNTIFS('Raw Data'!$C$2:$C$251,$A34,'Raw Data'!$B$2:$B$251,">"&$B$5)>0,1,0) -> 1 | U34: =IF(S34=1,SUM($S$23:S34),"") -> 10 | V34: =IF(T34=1,SUM($T$23:T34),"") -> 12 | W34: =TODAY()-J34 -> 703
... A72: CUST050 | B72: =INDEX('Raw Data'!$D$2:$D$251,MATCH($A72,'Raw Data'!$C$2:$C$251,0)) -> Julie Foster | C72: =UPPER(LEFT(B72,1)&MID(B72,FIND(" ",B72)+1,1)) -> JF | D72: =UPPER(LEFT(B72,1)&MID(B72,FIND(" ",B72)+1,3))&"-"&TEXT(VALUE(RIGHT(A72,3)),"000") -> JFOS-050 | E72: =COUNTIF('Raw Data'!$C$2:$C$251,$A72) -> 1 | F72: =SUMIF('Raw Data'!$C$2:$C$251,$A72,'Raw Data'!$H$2:$H$251) -> 4 | G72: =SUMIF('Raw Data'!$C$2:$C$251,$A72,'Raw Data'!$N$2:$N$251) -> 239.96 | H72: =IFERROR(G72/E72,0) -> 239.96 | I72: =_xlfn.MINIFS('Raw Data'!$B$2:$B$251,'Raw Data'!$C$2:$C$251,$A72) -> 45452 | J72: =_xlfn.MAXIFS('Raw Data'!$B$2:$B$251,'Raw Data'!$C$2:$C$251,$A72) -> 45452 | K72: =_xlfn.MINIFS('Raw Data'!$M$2:$M$251,'Raw Data'!$C$2:$C$251,$A72) -> 44435 | L72: =DATEDIF(K72,TODAY(),"Y") -> 5 | M72: =IF(_xlfn.MAXIFS('Raw Data'!$M$2:$M$251,'Raw Data'!$C$2:$C$251,$A72)-_xlfn.MINIFS('Raw Data'!$M$2:$M$251,'Raw Data'!$C$2:$C$251,$A72)>0,"Yes","No") -> No | N72: =RANK(G72,$G$23:$G$72,0) -> 49 | O72: =N72+COUNTIF($N$23:N72,N72)-1 -> 49 | P72: =IF(G72>=$B$4,"High-Value","Standard") -> Standard | Q72: =IF(E72>1,"Repeat","One-time") -> One-time | R72: =RANK(E72,$E$23:$E$72,0)+COUNTIF($E$23:E72,E72)-1 -> 50 | S72: =IF(COUNTIFS('Raw Data'!$C$2:$C$251,$A72,'Raw Data'!$B$2:$B$251,"<="&$B$5)>0,1,0) -> 1 | T72: =IF(COUNTIFS('Raw Data'!$C$2:$C$251,$A72,'Raw Data'!$B$2:$B$251,">"&$B$5)>0,1,0) -> 0 | U72: =IF(S72=1,SUM($S$23:S72),"") -> 46 | V72: =IF(T72=1,SUM($T$23:T72),"") | W72: =TODAY()-J72 -> 858

Sheet Names & Lists
A1: Names & Lists - Frequent Products, Repeating Names, List Comparison, Abbreviations
A4: 1. Most Frequently Purchased Product (COUNTIF / SUMIF on Raw Data) | H4: 4. Abbreviations with TEXT / string functions
A5: Product | B5: Orders (count) | C5: Units | D5: Revenue | E5: Orders Rank | H5: Product | I5: Abbreviation | J5: Category Code
