Workbook

Sheet Settings
A1: Settings & Assumptions (all formulas reference these cells with absolute references)
A3: Grade | B3: Min Average | C3: Note
A4: A+ | B4: 90 | C4: Average score at or above this → grade
A5: A | B5: 80
A6: B | B6: 70
A7: C | B7: 60
A8: D | B8: 50
A9: F | B9: < D | C9: Below the D cut-off
A11: Grade filter cut-off (Average above) | B11: 80 | C11: Used by FILTER: students with grade above 80
A12: Math & Science cut-off (each above) | B12: 80 | C12: Used by IF(AND(...))
A14: Discount Tier | B14: Min Sale Amount | C14: Discount %
A15: Tier 1 | B15: 40000 | C15: 0.15
A16: Tier 2 | B16: 25000 | C16: 0.1
A17: Tier 3 | B17: 10000 | C17: 0.05
A18: Below lowest tier | B18: - | C18: 0
A20: Discount eligibility: min amount | B20: 25000 | C20: Eligible if Amount ≥ this OR Region = promo region
A21: Promo region (always eligible) | B21: West
A23: GST rate | B23: 0.18 | C23: Assumption: 18% GST
A24: Rounding step – sales (₹) | B24: 10 | C24: Significance for CEILING / FLOOR
A25: Rounding step – salary (₹) | B25: 1000 | C25: Significance for CEILING / FLOOR

Sheet Price_List
A1: Product Price List (assumed – source sales data has no price column)
A3: Product Code | B3: Product | C3: Unit Price (₹)
A4: P-101 | B4: Keyboard | C4: 1500
A5: P-102 | B5: Mouse | C5: 800
A6: P-103 | B6: Printer | C6: 8000
A7: P-104 | B7: Monitor | C7: 12000
A8: P-105 | B8: Laptop | C8: 45000

Sheet Students
A1: Student ID | B1: Name | C1: Math | D1: Science | E1: English | F1: Enrollment Date | G1: Total | H1: Average | I1: Grade (Nested IF) | J1: Math & Science > 80 (IF-AND) | K1: Rank (unique)
A2: 1001 | B2: Student 1 | C2: 61 | D2: 48 | E2: 76 | F2: 43101 | G2: =SUM(C2:E2) -> 185 | H2: =ROUND(AVERAGE(C2:E2),2) -> 61.67 | I2: =IF(H2>=Settings!$B$4,Settings!$A$4,IF(H2>=Settings!$B$5,Settings!$A$5,IF(H2>=Settings!$B$6,Settings!$A$6,IF(H2>=Settings!$B$7,Settings!$A$7,IF(H2>=Settings!$B$8,Settings!$A$8,Settings!$A$9))))) -> C | J2: =IF(AND(C2>Settings!$B$12,D2>Settings!$B$12),"Yes","No") -> No | K2: =RANK(G2,$G$2:$G$21,0)+COUNTIF($G$2:G2,G2)-1 -> 16
A3: 1002 | B3: Student 2 | C3: 78 | D3: 76 | E3: 70 | F3: 43281 | G3: =SUM(C3:E3) -> 224 | H3: =ROUND(AVERAGE(C3:E3),2) -> 74.67 | I3: =IF(H3>=Settings!$B$4,Settings!$A$4,IF(H3>=Settings!$B$5,Settings!$A$5,IF(H3>=Settings!$B$6,Settings!$A$6,IF(H3>=Settings!$B$7,Settings!$A$7,IF(H3>=Settings!$B$8,Settings!$A$8,Settings!$A$9))))) -> B | J3: =IF(AND(C3>Settings!$B$12,D3>Settings!$B$12),"Yes","No") -> No | K3: =RANK(G3,$G$2:$G$21,0)+COUNTIF($G$2:G3,G3)-1 -> 8
A4: 1003 | B4: Student 3 | C4: 97 | D4: 60 | E4: 51 | F4: 43461 | G4: =SUM(C4:E4) -> 208 | H4: =ROUND(AVERAGE(C4:E4),2) -> 69.33 | I4: =IF(H4>=Settings!$B$4,Settings!$A$4,IF(H4>=Settings!$B$5,Settings!$A$5,IF(H4>=Settings!$B$6,Settings!$A$6,IF(H4>=Settings!$B$7,Settings!$A$7,IF(H4>=Settings!$B$8,Settings!$A$8,Settings!$A$9))))) -> C | J4: =IF(AND(C4>Settings!$B$12,D4>Settings!$B$12),"Yes","No") -> No | K4: =RANK(G4,$G$2:$G$21,0)+COUNTIF($G$2:G4,G4)-1 -> 12
A5: 1004 | B5: Student 4 | C5: 74 | D5: 55 | E5: 46 | F5: 43641 | G5: =SUM(C5:E5) -> 175 | H5: =ROUND(AVERAGE(C5:E5),2) -> 58.33 | I5: =IF(H5>=Settings!$B$4,Settings!$A$4,IF(H5>=Settings!$B$5,Settings!$A$5,IF(H5>=Settings!$B$6,Settings!$A$6,IF(H5>=Settings!$B$7,Settings!$A$7,IF(H5>=Settings!$B$8,Settings!$A$8,Settings!$A$9))))) -> D | J5: =IF(AND(C5>Settings!$B$12,D5>Settings!$B$12),"Yes","No") -> No | K5: =RANK(G5,$G$2:$G$21,0)+COUNTIF($G$2:G5,G5)-1 -> 18
A6: 1005 | B6: Student 5 | C6: 68 | D6: 74 | E6: 84 | F6: 43821 | G6: =SUM(C6:E6) -> 226 | H6: =ROUND(AVERAGE(C6:E6),2) -> 75.33 | I6: =IF(H6>=Settings!$B$4,Settings!$A$4,IF(H6>=Settings!$B$5,Settings!$A$5,IF(H6>=Settings!$B$6,Settings!$A$6,IF(H6>=Settings!$B$7,Settings!$A$7,IF(H6>=Settings!$B$8,Settings!$A$8,Settings!$A$9))))) -> B | J6: =IF(AND(C6>Settings!$B$12,D6>Settings!$B$12),"Yes","No") -> No | K6: =RANK(G6,$G$2:$G$21,0)+COUNTIF($G$2:G6,G6)-1 -> 6
A7: 1006 | B7: Student 6 | C7: 80 | D7: 70 | E7: 65 | F7: 44001 | G7: =SUM(C7:E7) -> 215 | H7: =ROUND(AVERAGE(C7:E7),2) -> 71.67 | I7: =IF(H7>=Settings!$B$4,Settings!$A$4,IF(H7>=Settings!$B$5,Settings!$A$5,IF(H7>=Settings!$B$6,Settings!$A$6,IF(H7>=Settings!$B$7,Settings!$A$7,IF(H7>=Settings!$B$8,Settings!$A$8,Settings!$A$9))))) -> B | J7: =IF(AND(C7>Settings!$B$12,D7>Settings!$B$12),"Yes","No") -> No | K7: =RANK(G7,$G$2:$G$21,0)+COUNTIF($G$2:G7,G7)-1 -> 9
A8: 1007 | B8: Student 7 | C8: 75 | D8: 47 | E8: 78 | F8: 44181 | G8: =SUM(C8:E8) -> 200 | H8: =ROUND(AVERAGE(C8:E8),2) -> 66.67 | I8: =IF(H8>=Settings!$B$4,Settings!$A$4,IF(H8>=Settings!$B$5,Settings!$A$5,IF(H8>=Settings!$B$6,Settings!$A$6,IF(H8>=Settings!$B$7,Settings!$A$7,IF(H8>=Settings!$B$8,Settings!$A$8,Settings!$A$9))))) -> C | J8: =IF(AND(C8>Settings!$B$12,D8>Settings!$B$12),"Yes","No") -> No | K8: =RANK(G8,$G$2:$G$21,0)+COUNTIF($G$2:G8,G8)-1 -> 14
A9: 1008 | B9: Student 8 | C9: 94 | D9: 67 | E9: 64 | F9: 44361 | G9: =SUM(C9:E9) -> 225 | H9: =ROUND(AVERAGE(C9:E9),2) -> 75 | I9: =IF(H9>=Settings!$B$4,Settings!$A$4,IF(H9>=Settings!$B$5,Settings!$A$5,IF(H9>=Settings!$B$6,Settings!$A$6,IF(H9>=Settings!$B$7,Settings!$A$7,IF(H9>=Settings!$B$8,Settings!$A$8,Settings!$A$9))))) -> B | J9: =IF(AND(C9>Settings!$B$12,D9>Settings!$B$12),"Yes","No") -> No | K9: =RANK(G9,$G$2:$G$21,0)+COUNTIF($G$2:G9,G9)-1 -> 7
A10: 1009 | B10: Student 9 | C10: 41 | D10: 75 | E10: 56 | F10: 44541 | G10: =SUM(C10:E10) -> 172 | H10: =ROUND(AVERAGE(C10:E10),2) -> 57.33 | I10: =IF(H10>=Settings!$B$4,Settings!$A$4,IF(H10>=Settings!$B$5,Settings!$A$5,IF(H10>=Settings!$B$6,Settings!$A$6,IF(H10>=Settings!$B$7,Settings!$A$7,IF(H10>=Settings!$B$8,Settings!$A$8,Settings!$A$9))))) -> D | J10: =IF(AND(C10>Settings!$B$12,D10>Settings!$B$12),"Yes","No") -> No | K10: =RANK(G10,$G$2:$G$21,0)+COUNTIF($G$2:G10,G10)-1 -> 19
A11: 1010 | B11: Student 10 | C11: 98 | D11: 54 | E11: 58 | F11: 44721 | G11: =SUM(C11:E11) -> 210 | H11: =ROUND(AVERAGE(C11:E11),2) -> 70 | I11: =IF(H11>=Settings!$B$4,Settings!$A$4,IF(H11>=Settings!$B$5,Settings!$A$5,IF(H11>=Settings!$B$6,Settings!$A$6,IF(H11>=Settings!$B$7,Settings!$A$7,IF(H11>=Settings!$B$8,Settings!$A$8,Settings!$A$9))))) -> B | J11: =IF(AND(C11>Settings!$B$12,D11>Settings!$B$12),"Yes","No") -> No | K11: =RANK(G11,$G$2:$G$21,0)+COUNTIF($G$2:G11,G11)-1 -> 10
A12: 1011 | B12: Student 11 | C12: 73 | D12: 79 | E12: 53 | F12: 44901 | G12: =SUM(C12:E12) -> 205 | H12: =ROUND(AVERAGE(C12:E12),2) -> 68.33 | I12: =IF(H12>=Settings!$B$4,Settings!$A$4,IF(H12>=Settings!$B$5,Settings!$A$5,IF(H12>=Settings!$B$6,Settings!$A$6,IF(H12>=Settings!$B$7,Settings!$A$7,IF(H12>=Settings!$B$8,Settings!$A$8,Settings!$A$9))))) -> C | J12: =IF(AND(C12>Settings!$B$12,D12>Settings!$B$12),"Yes","No") -> No | K12: =RANK(G12,$G$2:$G$21,0)+COUNTIF($G$2:G12,G12)-1 -> 13
A13: 1012 | B13: Student 12 | C13: 85 | D13: 89 | E13: 79 | F13: 45081 | G13: =SUM(C13:E13) -> 253 | H13: =ROUND(AVERAGE(C13:E13),2) -> 84.33 | I13: =IF(H13>=Settings!$B$4,Settings!$A$4,IF(H13>=Settings!$B$5,Settings!$A$5,IF(H13>=Settings!$B$6,Settings!$A$6,IF(H13>=Settings!$B$7,Settings!$A$7,IF(H13>=Settings!$B$8,Settings!$A$8,Settings!$A$9))))) -> A | J13: =IF(AND(C13>Settings!$B$12,D13>Settings!$B$12),"Yes","No") -> Yes | K13: =RANK(G13,$G$2:$G$21,0)+COUNTIF($G$2:G13,G13)-1 -> 2
... A21: 1020 | B21: Student 20 | C21: 83 | D21: 92 | E21: 55 | F21: 46521 | G21: =SUM(C21:E21) -> 230 | H21: =ROUND(AVERAGE(C21:E21),2) -> 76.67 | I21: =IF(H21>=Settings!$B$4,Settings!$A$4,IF(H21>=Settings!$B$5,Settings!$A$5,IF(H21>=Settings!$B$6,Settings!$A$6,IF(H21>=Settings!$B$7,Settings!$A$7,IF(H21>=Settings!$B$8,Settings!$A$8,Settings!$A$9))))) -> B | J21: =IF(AND(C21>Settings!$B$12,D21>Settings!$B$12),"Yes","No") -> Yes | K21: =RANK(G21,$G$2:$G$21,0)+COUNTIF($G$2:G21,G21)-1 -> 4

Sheet Sales
A1: Sales ID | B1: Product | C1: Region | D1: Salesperson | E1: Amount | F1: Date | G1: Unit Price (VLOOKUP) | H1: Discount % (Nested IF) | I1: Discount Amount | J1: Net Amount | K1: Discount Eligible (IF-OR) | L1: Lookup Key | M1: Month | N1: Net Rounded Up (CEILING) | O1: Net Rounded Down (FLOOR) | P1: Rolling 3-Sale Avg (OFFSET)
A2: 2001 | B2: Keyboard | C2: South | D2: Person 1 | E2: 7048 | F2: 44927 | G2: =VLOOKUP(B2,Price_List!$B$4:$C$8,2,FALSE) -> 1500 | H2: =IF(E2>=Settings!$B$15,Settings!$C$15,IF(E2>=Settings!$B$16,Settings!$C$16,IF(E2>=Settings!$B$17,Settings!$C$17,Settings!$C$18))) -> 0 | I2: =ROUND(E2*H2,0) -> 0 | J2: =E2-I2 -> 7048 | K2: =IF(OR(E2>=Settings!$B$20,C2=Settings!$B$21),"Eligible","Not Eligible") -> Not Eligible | L2: =D2&"|"&TEXT(F2,"yyyy-mm") -> Person 1|2023-01 | M2: =TEXT(F2,"mmm-yyyy") -> Jan-2023 | N2: =CEILING(J2,Settings!$B$24) -> 7050 | O2: =FLOOR(J2,Settings!$B$24) -> 7040 | P2: =IF(ROWS($E$2:E2)<3,"",ROUND(AVERAGE(OFFSET(E2,-2,0,3,1)),0))
A3: 2002 | B3: Printer | C3: West | D3: Person 2 | E3: 17428 | F3: 44942 | G3: =VLOOKUP(B3,Price_List!$B$4:$C$8,2,FALSE) -> 8000 | H3: =IF(E3>=Settings!$B$15,Settings!$C$15,IF(E3>=Settings!$B$16,Settings!$C$16,IF(E3>=Settings!$B$17,Settings!$C$17,Settings!$C$18))) -> 0.05 | I3: =ROUND(E3*H3,0) -> 871 | J3: =E3-I3 -> 16557 | K3: =IF(OR(E3>=Settings!$B$20,C3=Settings!$B$21),"Eligible","Not Eligible") -> Eligible | L3: =D3&"|"&TEXT(F3,"yyyy-mm") -> Person 2|2023-01 | M3: =TEXT(F3,"mmm-yyyy") -> Jan-2023 | N3: =CEILING(J3,Settings!$B$24) -> 16560 | O3: =FLOOR(J3,Settings!$B$24) -> 16550 | P3: =IF(ROWS($E$2:E3)<3,"",ROUND(AVERAGE(OFFSET(E3,-2,0,3,1)),0))
A4: 2003 | B4: Mouse | C4: South | D4: Person 3 | E4: 23672 | F4: 44957 | G4: =VLOOKUP(B4,Price_List!$B$4:$C$8,2,FALSE) -> 800 | H4: =IF(E4>=Settings!$B$15,Settings!$C$15,IF(E4>=Settings!$B$16,Settings!$C$16,IF(E4>=Settings!$B$17,Settings!$C$17,Settings!$C$18))) -> 0.05 | I4: =ROUND(E4*H4,0) -> 1184 | J4: =E4-I4 -> 22488 | K4: =IF(OR(E4>=Settings!$B$20,C4=Settings!$B$21),"Eligible","Not Eligible") -> Not Eligible | L4: =D4&"|"&TEXT(F4,"yyyy-mm") -> Person 3|2023-01 | M4: =TEXT(F4,"mmm-yyyy") -> Jan-2023 | N4: =CEILING(J4,Settings!$B$24) -> 22490 | O4: =FLOOR(J4,Settings!$B$24) -> 22480 | P4: =IF(ROWS($E$2:E4)<3,"",ROUND(AVERAGE(OFFSET(E4,-2,0,3,1)),0)) -> 16049
A5: 2004 | B5: Printer | C5: East | D5: Person 4 | E5: 5264 | F5: 44972 | G5: =VLOOKUP(B5,Price_List!$B$4:$C$8,2,FALSE) -> 8000 | H5: =IF(E5>=Settings!$B$15,Settings!$C$15,IF(E5>=Settings!$B$16,Settings!$C$16,IF(E5>=Settings!$B$17,Settings!$C$17,Settings!$C$18))) -> 0 | I5: =ROUND(E5*H5,0) -> 0 | J5: =E5-I5 -> 5264 | K5: =IF(OR(E5>=Settings!$B$20,C5=Settings!$B$21),"Eligible","Not Eligible") -> Not Eligible | L5: =D5&"|"&TEXT(F5,"yyyy-mm") -> Person 4|2023-02 | M5: =TEXT(F5,"mmm-yyyy") -> Feb-2023 | N5: =CEILING(J5,Settings!$B$24) -> 5270 | O5: =FLOOR(J5,Settings!$B$24) -> 5260 | P5: =IF(ROWS($E$2:E5)<3,"",ROUND(AVERAGE(OFFSET(E5,-2,0,3,1)),0)) -> 15455
A6: 2005 | B6: Keyboard | C6: North | D6: Person 5 | E6: 43388 | F6: 44987 | G6: =VLOOKUP(B6,Price_List!$B$4:$C$8,2,FALSE) -> 1500 | H6: =IF(E6>=Settings!$B$15,Settings!$C$15,IF(E6>=Settings!$B$16,Settings!$C$16,IF(E6>=Settings!$B$17,Settings!$C$17,Settings!$C$18))) -> 0.15 | I6: =ROUND(E6*H6,0) -> 6508 | J6: =E6-I6 -> 36880 | K6: =IF(OR(E6>=Settings!$B$20,C6=Settings!$B$21),"Eligible","Not Eligible") -> Eligible | L6: =D6&"|"&TEXT(F6,"yyyy-mm") -> Person 5|2023-03 | M6: =TEXT(F6,"mmm-yyyy") -> Mar-2023 | N6: =CEILING(J6,Settings!$B$24) -> 36880 | O6: =FLOOR(J6,Settings!$B$24) -> 36880 | P6: =IF(ROWS($E$2:E6)<3,"",ROUND(AVERAGE(OFFSET(E6,-2,0,3,1)),0)) -> 24108
A7: 2006 | B7: Mouse | C7: North | D7: Person 6 | E7: 19757 | F7: 45002 | G7: =VLOOKUP(B7,Price_List!$B$4:$C$8,2,FALSE) -> 800 | H7: =IF(E7>=Settings!$B$15,Settings!$C$15,IF(E7>=Settings!$B$16,Settings!$C$16,IF(E7>=Settings!$B$17,Settings!$C$17,Settings!$C$18))) -> 0.05 | I7: =ROUND(E7*H7,0) -> 988 | J7: =E7-I7 -> 18769 | K7: =IF(OR(E7>=Settings!$B$20,C7=Settings!$B$21),"Eligible","Not Eligible") -> Not Eligible | L7: =D7&"|"&TEXT(F7,"yyyy-mm") -> Person 6|2023-03 | M7: =TEXT(F7,"mmm-yyyy") -> Mar-2023 | N7: =CEILING(J7,Settings!$B$24) -> 18770 | O7: =FLOOR(J7,Settings!$B$24) -> 18760 | P7: =IF(ROWS($E$2:E7)<3,"",ROUND(AVERAGE(OFFSET(E7,-2,0,3,1)),0)) -> 22803
A8: 2007 | B8: Mouse | C8: East | D8: Person 7 | E8: 32058 | F8: 45017 | G8: =VLOOKUP(B8,Price_List!$B$4:$C$8,2,FALSE) -> 800 | H8: =IF(E8>=Settings!$B$15,Settings!$C$15,IF(E8>=Settings!$B$16,Settings!$C$16,IF(E8>=Settings!$B$17,Settings!$C$17,Settings!$C$18))) -> 0.1 | I8: =ROUND(E8*H8,0) -> 3206 | J8: =E8-I8 -> 28852 | K8: =IF(OR(E8>=Settings!$B$20,C8=Settings!$B$21),"Eligible","Not Eligible") -> Eligible | L8: =D8&"|"&TEXT(F8,"yyyy-mm") -> Person 7|2023-04 | M8: =TEXT(F8,"mmm-yyyy") -> Apr-2023 | N8: =CEILING(J8,Settings!$B$24) -> 28860 | O8: =FLOOR(J8,Settings!$B$24) -> 28850 | P8: =IF(ROWS($E$2:E8)<3,"",ROUND(AVERAGE(OFFSET(E8,-2,0,3,1)),0)) -> 31734
A9: 2008 | B9: Keyboard | C9: East | D9: Person 8 | E9: 46429 | F9: 45032 | G9: =VLOOKUP(B9,Price_List!$B$4:$C$8,2,FALSE) -> 1500 | H9: =IF(E9>=Settings!$B$15,Settings!$C$15,IF(E9>=Settings!$B$16,Settings!$C$16,IF(E9>=Settings!$B$17,Settings!$C$17,Settings!$C$18))) -> 0.15 | I9: =ROUND(E9*H9,0) -> 6964 | J9: =E9-I9 -> 39465 | K9: =IF(OR(E9>=Settings!$B$20,C9=Settings!$B$21),"Eligible","Not Eligible") -> Eligible | L9: =D9&"|"&TEXT(F9,"yyyy-mm") -> Person 8|2023-04 | M9: =TEXT(F9,"mmm-yyyy") -> Apr-2023 | N9: =CEILING(J9,Settings!$B$24) -> 39470 | O9: =FLOOR(J9,Settings!$B$24) -> 39460 | P9: =IF(ROWS($E$2:E9)<3,"",ROUND(AVERAGE(OFFSET(E9,-2,0,3,1)),0)) -> 32748
A10: 2009 | B10: Printer | C10: East | D10: Person 9 | E10: 19746 | F10: 45047 | G10: =VLOOKUP(B10,Price_List!$B$4:$C$8,2,FALSE) -> 8000 | H10: =IF(E10>=Settings!$B$15,Settings!$C$15,IF(E10>=Settings!$B$16,Settings!$C$16,IF(E10>=Settings!$B$17,Settings!$C$17,Settings!$C$18))) -> 0.05 | I10: =ROUND(E10*H10,0) -> 987 | J10: =E10-I10 -> 18759 | K10: =IF(OR(E10>=Settings!$B$20,C10=Settings!$B$21),"Eligible","Not Eligible") -> Not Eligible | L10: =D10&"|"&TEXT(F10,"yyyy-mm") -> Person 9|2023-05 | M10: =TEXT(F10,"mmm-yyyy") -> May-2023 | N10: =CEILING(J10,Settings!$B$24) -> 18760 | O10: =FLOOR(J10,Settings!$B$24) -> 18750 | P10: =IF(ROWS($E$2:E10)<3,"",ROUND(AVERAGE(OFFSET(E10,-2,0,3,1)),0)) -> 32744
A11: 2010 | B11: Keyboard | C11: South | D11: Person 10 | E11: 35185 | F11: 45062 | G11: =VLOOKUP(B11,Price_List!$B$4:$C$8,2,FALSE) -> 1500 | H11: =IF(E11>=Settings!$B$15,Settings!$C$15,IF(E11>=Settings!$B$16,Settings!$C$16,IF(E11>=Settings!$B$17,Settings!$C$17,Settings!$C$18))) -> 0.1 | I11: =ROUND(E11*H11,0) -> 3519 | J11: =E11-I11 -> 31666 | K11: =IF(OR(E11>=Settings!$B$20,C11=Settings!$B$21),"Eligible","Not Eligible") -> Eligible | L11: =D11&"|"&TEXT(F11,"yyyy-mm") -> Person 10|2023-05 | M11: =TEXT(F11,"mmm-yyyy") -> May-2023 | N11: =CEILING(J11,Settings!$B$24) -> 31670 | O11: =FLOOR(J11,Settings!$B$24) -> 31660 | P11: =IF(ROWS($E$2:E11)<3,"",ROUND(AVERAGE(OFFSET(E11,-2,0,3,1)),0)) -> 33787
A12: 2011 | B12: Keyboard | C12: East | D12: Person 11 | E12: 33920 | F12: 45077 | G12: =VLOOKUP(B12,Price_List!$B$4:$C$8,2,FALSE) -> 1500 | H12: =IF(E12>=Settings!$B$15,Settings!$C$15,IF(E12>=Settings!$B$16,Settings!$C$16,IF(E12>=Settings!$B$17,Settings!$C$17,Settings!$C$18))) -> 0.1 | I12: =ROUND(E12*H12,0) -> 3392 | J12: =E12-I12 -> 30528 | K12: =IF(OR(E12>=Settings!$B$20,C12=Settings!$B$21),"Eligible","Not Eligible") -> Eligible | L12: =D12&"|"&TEXT(F12,"yyyy-mm") -> Person 11|2023-05 | M12: =TEXT(F12,"mmm-yyyy") -> May-2023 | N12: =CEILING(J12,Settings!$B$24) -> 30530 | O12: =FLOOR(J12,Settings!$B$24) -> 30520 | P12: =IF(ROWS($E$2:E12)<3,"",ROUND(AVERAGE(OFFSET(E12,-2,0,3,1)),0)) -> 29617
A13: 2012 | B13: Monitor | C13: North | D13: Person 12 | E13: 35611 | F13: 45092 | G13: =VLOOKUP(B13,Price_List!$B$4:$C$8,2,FALSE) -> 12000 | H13: =IF(E13>=Settings!$B$15,Settings!$C$15,IF(E13>=Settings!$B$16,Settings!$C$16,IF(E13>=Settings!$B$17,Settings!$C$17,Settings!$C$18))) -> 0.1 | I13: =ROUND(E13*H13,0) -> 3561 | J13: =E13-I13 -> 32050 | K13: =IF(OR(E13>=Settings!$B$20,C13=Settings!$B$21),"Eligible","Not Eligible") -> Eligible | L13: =D13&"|"&TEXT(F13,"yyyy-mm") -> Person 12|2023-06 | M13: =TEXT(F13,"mmm-yyyy") -> Jun-2023 | N13: =CEILING(J13,Settings!$B$24) -> 32050 | O13: =FLOOR(J13,Settings!$B$24) -> 32050 | P13: =IF(ROWS($E$2:E13)<3,"",ROUND(AVERAGE(OFFSET(E13,-2,0,3,1)),0)) -> 34905
... A21: 2020 | B21: Printer | C21: West | D21: Person 20 | E21: 33953 | F21: 45212 | G21: =VLOOKUP(B21,Price_List!$B$4:$C$8,2,FALSE) -> 8000 | H21: =IF(E21>=Settings!$B$15,Settings!$C$15,IF(E21>=Settings!$B$16,Settings!$C$16,IF(E21>=Settings!$B$17,Settings!$C$17,Settings!$C$18))) -> 0.1 | I21: =ROUND(E21*H21,0) -> 3395 | J21: =E21-I21 -> 30558 | K21: =IF(OR(E21>=Settings!$B$20,C21=Settings!$B$21),"Eligible","Not Eligible") -> Eligible | L21: =D21&"|"&TEXT(F21,"yyyy-mm") -> Person 20|2023-10 | M21: =TEXT(F21,"mmm-yyyy") -> Oct-2023 | N21: =CEILING(J21,Settings!$B$24) -> 30560 | O21: =FLOOR(J21,Settings!$B$24) -> 30550 | P21: =IF(ROWS($E$2:E21)<3,"",ROUND(AVERAGE(OFFSET(E21,-2,0,3,1)),0)) -> 34183

Sheet Employees
A1: Employee ID | B1: Name | C1: Department | D1: Salary | E1: Joining Date | F1: Join Year | G1: Join Month | H1: Join Weekday | I1: Status | J1: Tenure (Years) | K1: Tenure (Days) | L1: First Name (LEFT+FIND) | M1: UPPER | N1: lower | O1: Monthly Salary (ROUND) | P1: Salary Rounded Up (CEILING) | Q1: Salary Rounded Down (FLOOR)
A2: 3001 | B2: Employee 1 | C2: Finance | D2: 86766 | E2: 42005 | F2: =YEAR(E2) -> 2015 | G2: =TEXT(E2,"mmmm") -> January | H2: =TEXT(E2,"dddd") -> Thursday | I2: =IF(E2>TODAY(),"Joining Soon","Active") -> Active | J2: =IF(E2>TODAY(),0,DATEDIF(E2,TODAY(),"y")) -> 11 | K2: =MAX(0,TODAY()-E2) -> 4305 | L2: =LEFT(B2,FIND(" ",B2)-1) -> Employee | M2: =UPPER(B2) -> EMPLOYEE 1 | N2: =LOWER(B2) -> employee 1 | O2: =ROUND(D2/12,0) -> 7231 | P2: =CEILING(D2,Settings!$B$25) -> 87000 | Q2: =FLOOR(D2,Settings!$B$25) -> 86000
A3: 3002 | B3: Employee 2 | C3: Finance | D3: 31943 | E3: 42255 | F3: =YEAR(E3) -> 2015 | G3: =TEXT(E3,"mmmm") -> September | H3: =TEXT(E3,"dddd") -> Tuesday | I3: =IF(E3>TODAY(),"Joining Soon","Active") -> Active | J3: =IF(E3>TODAY(),0,DATEDIF(E3,TODAY(),"y")) -> 11 | K3: =MAX(0,TODAY()-E3) -> 4055 | L3: =LEFT(B3,FIND(" ",B3)-1) -> Employee | M3: =UPPER(B3) -> EMPLOYEE 2 | N3: =LOWER(B3) -> employee 2 | O3: =ROUND(D3/12,0) -> 2662 | P3: =CEILING(D3,Settings!$B$25) -> 32000 | Q3: =FLOOR(D3,Settings!$B$25) -> 31000
A4: 3003 | B4: Employee 3 | C4: HR | D4: 63374 | E4: 42505 | F4: =YEAR(E4) -> 2016 | G4: =TEXT(E4,"mmmm") -> May | H4: =TEXT(E4,"dddd") -> Sunday | I4: =IF(E4>TODAY(),"Joining Soon","Active") -> Active | J4: =IF(E4>TODAY(),0,DATEDIF(E4,TODAY(),"y")) -> 10 | K4: =MAX(0,TODAY()-E4) -> 3805 | L4: =LEFT(B4,FIND(" ",B4)-1) -> Employee | M4: =UPPER(B4) -> EMPLOYEE 3 | N4: =LOWER(B4) -> employee 3 | O4: =ROUND(D4/12,0) -> 5281 | P4: =CEILING(D4,Settings!$B$25) -> 64000 | Q4: =FLOOR(D4,Settings!$B$25) -> 63000
A5: 3004 | B5: Employee 4 | C5: Finance | D5: 109972 | E5: 42755 | F5: =YEAR(E5) -> 2017 | G5: =TEXT(E5,"mmmm") -> January | H5: =TEXT(E5,"dddd") -> Friday | I5: =IF(E5>TODAY(),"Joining Soon","Active") -> Active | J5: =IF(E5>TODAY(),0,DATEDIF(E5,TODAY(),"y")) -> 9 | K5: =MAX(0,TODAY()-E5) -> 3555 | L5: =LEFT(B5,FIND(" ",B5)-1) -> Employee | M5: =UPPER(B5) -> EMPLOYEE 4 | N5: =LOWER(B5) -> employee 4 | O5: =ROUND(D5/12,0) -> 9164 | P5: =CEILING(D5,Settings!$B$25) -> 110000 | Q5: =FLOOR(D5,Settings!$B$25) -> 109000
A6: 3005 | B6: Employee 5 | C6: IT | D6: 54149 | E6: 43005 | F6: =YEAR(E6) -> 2017 | G6: =TEXT(E6,"mmmm") -> September | H6: =TEXT(E6,"dddd") -> Wednesday | I6: =IF(E6>TODAY(),"Joining Soon","Active") -> Active | J6: =IF(E6>TODAY(),0,DATEDIF(E6,TODAY(),"y")) -> 9 | K6: =MAX(0,TODAY()-E6) -> 3305 | L6: =LEFT(B6,FIND(" ",B6)-1) -> Employee | M6: =UPPER(B6) -> EMPLOYEE 5 | N6: =LOWER(B6) -> employee 5 | O6: =ROUND(D6/12,0) -> 4512 | P6: =CEILING(D6,Settings!$B$25) -> 55000 | Q6: =FLOOR(D6,Settings!$B$25) -> 54000
A7: 3006 | B7: Employee 6 | C7: IT | D7: 78689 | E7: 43255 | F7: =YEAR(E7) -> 2018 | G7: =TEXT(E7,"mmmm") -> June | H7: =TEXT(E7,"dddd") -> Monday | I7: =IF(E7>TODAY(),"Joining Soon","Active") -> Active | J7: =IF(E7>TODAY(),0,DATEDIF(E7,TODAY(),"y")) -> 8 | K7: =MAX(0,TODAY()-E7) -> 3055 | L7: =LEFT(B7,FIND(" ",B7)-1) -> Employee | M7: =UPPER(B7) -> EMPLOYEE 6 | N7: =LOWER(B7) -> employee 6 | O7: =ROUND(D7/12,0) -> 6557 | P7: =CEILING(D7,Settings!$B$25) -> 79000 | Q7: =FLOOR(D7,Settings!$B$25) -> 78000
A8: 3007 | B8: Employee 7 | C8: Marketing | D8: 35960 | E8: 43505 | F8: =YEAR(E8) -> 2019 | G8: =TEXT(E8,"mmmm") -> February | H8: =TEXT(E8,"dddd") -> Saturday | I8: =IF(E8>TODAY(),"Joining Soon","Active") -> Active | J8: =IF(E8>TODAY(),0,DATEDIF(E8,TODAY(),"y")) -> 7 | K8: =MAX(0,TODAY()-E8) -> 2805 | L8: =LEFT(B8,FIND(" ",B8)-1) -> Employee | M8: =UPPER(B8) -> EMPLOYEE 7 | N8: =LOWER(B8) -> employee 7 | O8: =ROUND(D8/12,0) -> 2997 | P8: =CEILING(D8,Settings!$B$25) -> 36000 | Q8: =FLOOR(D8,Settings!$B$25) -> 35000
A9: 3008 | B9: Employee 8 | C9: IT | D9: 91659 | E9: 43755 | F9: =YEAR(E9) -> 2019 | G9: =TEXT(E9,"mmmm") -> October | H9: =TEXT(E9,"dddd") -> Thursday | I9: =IF(E9>TODAY(),"Joining Soon","Active") -> Active | J9: =IF(E9>TODAY(),0,DATEDIF(E9,TODAY(),"y")) -> 6 | K9: =MAX(0,TODAY()-E9) -> 2555 | L9: =LEFT(B9,FIND(" ",B9)-1) -> Employee | M9: =UPPER(B9) -> EMPLOYEE 8 | N9: =LOWER(B9) -> employee 8 | O9: =ROUND(D9/12,0) -> 7638 | P9: =CEILING(D9,Settings!$B$25) -> 92000 | Q9: =FLOOR(D9,Settings!$B$25) -> 91000
A10: 3009 | B10: Employee 9 | C10: IT | D10: 90423 | E10: 44005 | F10: =YEAR(E10) -> 2020 | G10: =TEXT(E10,"mmmm") -> June | H10: =TEXT(E10,"dddd") -> Tuesday | I10: =IF(E10>TODAY(),"Joining Soon","Active") -> Active | J10: =IF(E10>TODAY(),0,DATEDIF(E10,TODAY(),"y")) -> 6 | K10: =MAX(0,TODAY()-E10) -> 2305 | L10: =LEFT(B10,FIND(" ",B10)-1) -> Employee | M10: =UPPER(B10) -> EMPLOYEE 9 | N10: =LOWER(B10) -> employee 9 | O10: =ROUND(D10/12,0) -> 7535 | P10: =CEILING(D10,Settings!$B$25) -> 91000 | Q10: =FLOOR(D10,Settings!$B$25) -> 90000
A11: 3010 | B11: Employee 10 | C11: HR | D11: 107877 | E11: 44255 | F11: =YEAR(E11) -> 2021 | G11: =TEXT(E11,"mmmm") -> February | H11: =TEXT(E11,"dddd") -> Sunday | I11: =IF(E11>TODAY(),"Joining Soon","Active") -> Active | J11: =IF(E11>TODAY(),0,DATEDIF(E11,TODAY(),"y")) -> 5 | K11: =MAX(0,TODAY()-E11) -> 2055 | L11: =LEFT(B11,FIND(" ",B11)-1) -> Employee | M11: =UPPER(B11) -> EMPLOYEE 10 | N11: =LOWER(B11) -> employee 10 | O11: =ROUND(D11/12,0) -> 8990 | P11: =CEILING(D11,Settings!$B$25) -> 108000 | Q11: =FLOOR(D11,Settings!$B$25) -> 107000
A12: 3011 | B12: Employee 11 | C12: Finance | D12: 107634 | E12: 44505 | F12: =YEAR(E12) -> 2021 | G12: =TEXT(E12,"mmmm") -> November | H12: =TEXT(E12,"dddd") -> Friday | I12: =IF(E12>TODAY(),"Joining Soon","Active") -> Active | J12: =IF(E12>TODAY(),0,DATEDIF(E12,TODAY(),"y")) -> 4 | K12: =MAX(0,TODAY()-E12) -> 1805 | L12: =LEFT(B12,FIND(" ",B12)-1) -> Employee | M12: =UPPER(B12) -> EMPLOYEE 11 | N12: =LOWER(B12) -> employee 11 | O12: =ROUND(D12/12,0) -> 8970 | P12: =CEILING(D12,Settings!$B$25) -> 108000 | Q12: =FLOOR(D12,Settings!$B$25) -> 107000
A13: 3012 | B13: Employee 12 | C13: Finance | D13: 35226 | E13: 44755 | F13: =YEAR(E13) -> 2022 | G13: =TEXT(E13,"mmmm") -> July | H13: =TEXT(E13,"dddd") -> Wednesday | I13: =IF(E13>TODAY(),"Joining Soon","Active") -> Active | J13: =IF(E13>TODAY(),0,DATEDIF(E13,TODAY(),"y")) -> 4 | K13: =MAX(0,TODAY()-E13) -> 1555 | L13: =LEFT(B13,FIND(" ",B13)-1) -> Employee | M13: =UPPER(B13) -> EMPLOYEE 12 | N13: =LOWER(B13) -> employee 12 | O13: =ROUND(D13/12,0) -> 2936 | P13: =CEILING(D13,Settings!$B$25) -> 36000 | Q13: =FLOOR(D13,Settings!$B$25) -> 35000
... A21: 3020 | B21: Employee 20 | C21: Marketing | D21: 99924 | E21: 46755 | F21: =YEAR(E21) -> 2028 | G21: =TEXT(E21,"mmmm") -> January | H21: =TEXT(E21,"dddd") -> Monday | I21: =IF(E21>TODAY(),"Joining Soon","Active") -> Joining Soon | J21: =IF(E21>TODAY(),0,DATEDIF(E21,TODAY(),"y")) -> 0 | K21: =MAX(0,TODAY()-E21) -> 0 | L21: =LEFT(B21,FIND(" ",B21)-1) -> Employee | M21: =UPPER(B21) -> EMPLOYEE 20 | N21: =LOWER(B21) -> employee 20 | O21: =ROUND(D21/12,0) -> 8327 | P21: =CEILING(D21,Settings!$B$25) -> 100000 | Q21: =FLOOR(D21,Settings!$B$25) -> 99000

Sheet Analysis
A1: Formula Analysis – COUNTIFS, SUMIFS, Lookups, Dates, Math, FILTER
A4: Task | B4: Input 1 | C4: Input 2 | D4: Result
A5: 1. COUNTIFS / SUMIFS / AVERAGEIFS
A6: Students scoring ABOVE [Input 1] in Math | B6: 60 | D6: =COUNTIFS(Students!$C$2:$C$21,">"&B6) -> 19
A7: Students scoring ABOVE [Input 1] in ALL 3 subjects | B7: 60 | D7: =COUNTIFS(Students!$C$2:$C$21,">"&B7,Students!$D$2:$D$21,">"&B7,Students!$E$2:$E$21,">"&B7) -> 6
A8: Students scoring ABOVE [Input 1] in Math (essential task) | B8: 50 | D8: =COUNTIFS(Students!$C$2:$C$21,">"&B8) -> 19
A9: Total sales: Region [Input 1] & Product [Input 2] | B9: East | C9: Keyboard | D9: =SUMIFS(Sales!$E$2:$E$21,Sales!$C$2:$C$21,B9,Sales!$B$2:$B$21,C9) -> 80349
A10: Avg Math score of students scoring ABOVE [Input 1] | B10: 60 | D10: =AVERAGEIFS(Students!$C$2:$C$21,Students!$C$2:$C$21,">"&B10) -> 82.263158
A11: Avg of overall Average for students whose Average > [Input 1] | B11: 60 | D11: =AVERAGEIFS(Students!$H$2:$H$21,Students!$H$2:$H$21,">"&B11) -> 73.625
A12: Employees in Dept [Input 1] with salary above [Input 2] | B12: IT | C12: 90000 | D12: =COUNTIFS(Employees!$C$2:$C$21,B12,Employees!$D$2:$D$21,">"&C12) -> 3
A13: Average salary of Dept [Input 1] | B13: HR | D13: =AVERAGEIFS(Employees!$D$2:$D$21,Employees!$C$2:$C$21,B13) -> 69618.833
A15: 2. VLOOKUP
A16: Student name for Student ID [Input 1] | B16: 1005 | D16: =VLOOKUP(B16,Students!$A$2:$B$21,2,FALSE) -> Student 5
A17: Product price for Product Code [Input 1] | B17: P-103 | D17: =VLOOKUP(B17,Price_List!$A$4:$C$8,3,FALSE) -> 8000
A18: Product price for Product [Input 1] (sales data) | B18: Laptop | D18: =VLOOKUP(B18,Price_List!$B$4:$C$8,2,FALSE) -> 45000
A20: 3. INDEX & MATCH
A21: Sales value: Salesperson [Input 1] in month of [Input 2] | B21: Person 5 | C21: 44986 | D21: =IFERROR(INDEX(Sales!$E$2:$E$21,MATCH(B21&"|"&TEXT(C21,"yyyy-mm"),Sales!$L$2:$L$21,0)),"No sale") -> 43388
A22: Employee ID for details below | B22: 3008
A23: Employee detail – field [Input 1] | B23: Name | D23: =INDEX(Employees!$A$2:$E$21,MATCH($B$22,Employees!$A$2:$A$21,0),MATCH(B23,Employees!$A$1:$E$1,0)) -> Employee 8
A24: Employee detail – field [Input 1] | B24: Department | D24: =INDEX(Employees!$A$2:$E$21,MATCH($B$22,Employees!$A$2:$A$21,0),MATCH(B24,Employees!$A$1:$E$1,0)) -> IT
A25: Employee detail – field [Input 1] | B25: Salary | D25: =INDEX(Employees!$A$2:$E$21,MATCH($B$22,Employees!$A$2:$A$21,0),MATCH(B25,Employees!$A$1:$E$1,0)) -> 91659
A26: Employee detail – field [Input 1] | B26: Joining Date | D26: =INDEX(Employees!$A$2:$E$21,MATCH($B$22,Employees!$A$2:$A$21,0),MATCH(B26,Employees!$A$1:$E$1,0)) -> 43755
A28: 4. XLOOKUP
A29: Sales amount for Salesperson [Input 1] | B29: Person 8 | D29: =_xlfn.XLOOKUP(B29,Sales!$D$2:$D$21,Sales!$E$2:$E$21,"Not found") -> 46429
A30: Region for Sales ID [Input 1] | B30: 2012 | D30: =_xlfn.XLOOKUP(B30,Sales!$A$2:$A$21,Sales!$C$2:$C$21,"Not found") -> North
A31: Salary for Employee ID [Input 1] | B31: 3016 | D31: =_xlfn.XLOOKUP(B31,Employees!$A$2:$A$21,Employees!$D$2:$D$21,"Not found") -> 114173
A32: Salary for Employee name [Input 1] | B32: Employee 12 | D32: =_xlfn.XLOOKUP(B32,Employees!$B$2:$B$21,Employees!$D$2:$D$21,"Not found") -> 35226
A33: Salary for Employee ID [Input 1] (not in list) | B33: 9999 | D33: =_xlfn.XLOOKUP(B33,Employees!$A$2:$A$21,Employees!$D$2:$D$21,"Not found") -> Not found
A35: 5. XMATCH
A36: Position of first [Input 1] in the sales list | B36: Laptop | D36: =_xlfn.XMATCH(B36,Sales!$B$2:$B$21) -> 13
A37: Position of LAST [Input 1] in the sales list | B37: Laptop | D37: =_xlfn.XMATCH(B37,Sales!$B$2:$B$21,0,-1) -> 15
A39: 6. INDIRECT
A40: SUM of column [Input 2] on sheet [Input 1] | B40: Sales | C40: E | D40: =SUM(INDIRECT(B40&"!"&C40&"2:"&C40&"21")) -> 507725
A41: AVERAGE of column [Input 2] on sheet [Input 1] | B41: Employees | C41: D | D41: =AVERAGE(INDIRECT(B41&"!"&C41&"2:"&C41&"21")) -> 79339.9
A42: Student name at sheet row [Input 1] | B42: 5 | D42: =INDIRECT("Students!B"&B42) -> Student 4
A44: 7. OFFSET (dynamic ranges for sales trend)
A45: Sum of the latest [Input 1] sales | B45: 5 | D45: =SUM(OFFSET(Sales!$E$1,COUNT(Sales!$E$2:$E$21)-B45+1,0,B45,1)) -> 149698
A46: Avg of [Input 2] sales starting at sale # [Input 1] | B46: 6 | C46: 3 | D46: =AVERAGE(OFFSET(Sales!$E$1,B46,0,C46,1)) -> 32748
A48: 8. Date & Time functions
A49: Age (years) from Date of Birth [Input 1] (example DOB) | B49: 34926 | D49: =DATEDIF(B49,TODAY(),"y") -> 31
...
